Workbook

Sheet Mode d'emploi
A1: ORIENTech — comment remplir ce fichier
A3: 1. Onglet « Métiers » : une ligne par métier (M01 à M16). Remplace les textes en MAJUSCULES.
A4: • bacs et competences : plusieurs valeurs séparées par un point-virgule ;
A5: • etape1 à etape3 = le parcours ; etape_cible = le lieu de travail final (carte jaune).
A6: • La ligne grise en italique sous les en-têtes est un exemple : laisse-la ou supprime-la, elle est ignorée.
A8: 2. Onglet « Questions » : une ligne par question, puis pour CHAQUE métier :
A9: O = un élève fait pour ce métier répondrait OUI
A10: N = il répondrait NON
A11: ? = ça n'a pas d'importance pour ce métier (une case vide compte comme ?)
A12: • Colonne « exemple » (facultative) : une petite situation concrète pour aider l'élève à répondre.
A13: Elle s'affiche sous la question. Ex : « Tu passes ton samedi à monter une cabane ou à réparer ton vélo. »
A14: Reste court (une phrase, ~15 mots) pour que ça tienne dans la bulle.
... A34: • Le jeu pose au maximum 20 questions sur les 50 : le surplus sert à varier les parties. Rattachements pôle → famille, salaires, entreprises et cursus : propositions de travail à valider.

Sheet Questions
A1: id | B1: question | C1: exemple | D1: M01 | E1: M02 | F1: M03 | G1: M04 | H1: M05 | I1: M06 | J1: M07 | K1: M08 | L1: M09 | M1: M10 | N1: M11 | O1: M12 | P1: M13 | Q1: M14 | R1: M15 | S1: M16
C2: nom du métier → | D2: =Métiers!B3 | E2: =Métiers!B4 | F2: =Métiers!B5 | G2: =Métiers!B6 | H2: =Métiers!B7 | I2: =Métiers!B8 | J2: =Métiers!B9 | K2: =Métiers!B10 | L2: =Métiers!B11 | M2: =Métiers!B12 | N2: =Métiers!B13 | O2: =Métiers!B14 | P2: =Métiers!B15 | Q2: =Métiers!B16 | R2: =Métiers!B17 | S2: =Métiers!B18
A3: Q01 | B3: Tu aimes que tes fichiers soient rangés en dossiers très précis. | C3: Tu classes tes devoirs par année, matière et chapitre pour tout retrouver en un clic. | D3: N | E3: N | F3: N | G3: N | H3: O | I3: O | J3: O | K3: O | L3: N | M3: N | N3: N | O3: N | P3: O | Q3: O | R3: O | S3: O
A4: Q02 | B4: Monter sur scène devant un public, ça te met mal à l'aise. | C4: Pour le spectacle de fin d'année, tu préfères aider en coulisses que présenter. | D4: N | E4: N | F4: O | G4: O | H4: N | I4: N | J4: O | K4: O | L4: N | M4: N | N4: O | O4: O | P4: N | Q4: N | R4: O | S4: O
A5: Q03 | B5: En travail de groupe, tu te lances directement dans les recherches sans demander l'avis de chacun. | C5: Le sujet est donné : tu ouvres tout de suite l'ordinateur pour chercher des infos. | D5: O | E5: O | F5: O | G5: O | H5: O | I5: O | J5: O | K5: O | L5: N | M5: N | N5: N | O5: N | P5: N | Q5: N | R5: N | S5: N
A6: Q04 | B6: T'entraîner des heures seul(e) pour devenir le ou la meilleur(e), ça te lasse vite. | C6: Répéter seul(e) le même morceau de guitare, tu décroches au bout d'un moment. | D6: N | E6: O | F6: N | G6: O | H6: N | I6: O | J6: N | K6: O | L6: N | M6: O | N6: N | O6: O | P6: N | Q6: O | R6: N | S6: O
A7: Q05 | B7: Tu aimes inventer ta propre création sans suivre de notice. | C7: Tu ouvres une boîte de Lego et tu construis un vaisseau qui n'est pas sur la boîte. | D7: O | E7: O | F7: O | G7: O | H7: N | I7: N | J7: N | K7: N | L7: O | M7: O | N7: O | O7: O | P7: N | Q7: N | R7: N | S7: N
A8: Q06 | B8: Pendant un spectacle, tu préfères être sur scène plutôt qu'à la régie son et lumière. | C8: Au spectacle du collège, tu veux être sous les projecteurs, pas au fond de la salle. | D8: O | E8: O | F8: N | G8: N | H8: O | I8: O | J8: N | K8: N | L8: O | M8: O | N8: N | O8: N | P8: O | Q8: O | R8: N | S8: N
A9: Q07 | B9: Quand ton téléphone bugue, tu demandes de l'aide à quelqu'un plutôt que de fouiller dans les réglages. | C9: Ta console ne se connecte pas au Wi-Fi : tu demandes à un proche de regarder. | D9: N | E9: N | F9: N | G9: N | H9: N | I9: N | J9: N | K9: N | L9: O | M9: O | N9: O | O9: O | P9: O | Q9: O | R9: O | S9: O
A10: Q08 | B10: Quand tu as fini un travail, tu le rends sans forcément le relire. | C10: Ton devoir est terminé : tu le ranges dans ton sac sans y rejeter un œil. | D10: O | E10: O | F10: O | G10: O | H10: N | I10: N | J10: N | K10: N | L10: O | M10: O | N10: O | O10: O | P10: N | Q10: N | R10: N | S10: N
A11: Q09 | B11: Répartir le travail du groupe, tu préfères le laisser à quelqu'un d'autre. | C11: Pour l'exposé, tu prends ta partie et tu laisses un autre suivre l'avancement. | D11: O | E11: N | F11: O | G11: N | H11: O | I11: N | J11: O | K11: N | L11: O | M11: N | N11: O | O11: N | P11: O | Q11: N | R11: O | S11: N
A12: Q10 | B12: Que ton travail soit vu par tout le monde, ça t'importe peu. | C12: Ton dessin reste dans ton carnet : tu ne cherches pas à l'afficher. | D12: N | E12: N | F12: O | G12: O | H12: N | I12: N | J12: O | K12: O | L12: N | M12: N | N12: O | O12: O | P12: N | Q12: N | R12: O | S12: O
A13: Q11 | B13: Tu aimes demander les goûts de chacun pour organiser une fête. | C13: Pour une fête de classe, tu fais un sondage sur le gâteau et la musique. | D13: N | E13: N | F13: N | G13: N | H13: N | I13: N | J13: N | K13: N | L13: O | M13: O | N13: O | O13: O | P13: O | Q13: O | R13: O | S13: O
A14: Q12 | B14: En cuisine, tu suis la recette à la lettre et tu pèses tout. | C14: Pour un gâteau, tu mesures chaque ingrédient au gramme près. | D14: N | E14: N | F14: N | G14: N | H14: O | I14: O | J14: O | K14: O | L14: N | M14: N | N14: N | O14: N | P14: O | Q14: O | R14: O | S14: O
... A52: Q50 | B52: Avant un départ, tu prépares ton sac au dernier moment. | C52: Le matin de la sortie scolaire, tu remplis ton sac juste avant de partir. | D52: O | E52: O | F52: O | G52: O | H52: N | I52: N | J52: N | K52: N | L52: O | M52: O | N52: O | O52: O | P52: N | Q52: N | R52: N | S52: N

Sheet Questions familles
A1: id | B1: question | C1: exemple | D1: F01 | E1: F02 | F1: F03 | G1: F04 | H1: F05 | I1: F06 | J1: F07
C2: nom du métier → | D2: =Familles!B3 | E2: =Familles!B4 | F2: =Familles!B5 | G2: =Familles!B6 | H2: =Familles!B7 | I2: =Familles!B8 | J2: =Familles!B9
A3: Q01 | B3: Tu aimes que tes fichiers soient rangés en dossiers très précis. | C3: Tu classes tes devoirs par année, matière et chapitre pour tout retrouver en un clic. | D3: O | E3: N | F3: N | G3: ? | H3: N | I3: O | J3: O
A4: Q02 | B4: Monter sur scène devant un public, ça te met mal à l'aise. | C4: Pour le spectacle de fin d'année, tu préfères aider en coulisses que présenter. | D4: O | E4: ? | F4: N | G4: O | H4: N | I4: O | J4: N
A5: Q03 | B5: En travail de groupe, tu te lances directement dans les recherches sans demander l'avis de chacun. | C5: Le sujet est donné : tu ouvres tout de suite l'ordinateur pour chercher des infos. | D5: O | E5: O | F5: ? | G5: O | H5: N | I5: O | J5: N
A6: Q04 | B6: T'entraîner des heures seul(e) pour devenir le ou la meilleur(e), ça te lasse vite. | C6: Répéter seul(e) le même morceau de guitare, tu décroches au bout d'un moment. | D6: O | E6: N | F6: ? | G6: N | H6: O | I6: N | J6: O
A7: Q05 | B7: Tu aimes inventer ta propre création sans suivre de notice. | C7: Tu ouvres une boîte de Lego et tu construis un vaisseau qui n'est pas sur la boîte. | D7: N | E7: O | F7: O | G7: ? | H7: O | I7: N | J7: N
A8: Q06 | B8: Pendant un spectacle, tu préfères être sur scène plutôt qu'à la régie son et lumière. | C8: Au spectacle du collège, tu veux être sous les projecteurs, pas au fond de la salle. | D8: N | E8: ? | F8: O | G8: N | H8: O | I8: N | J8: O
A9: Q07 | B9: Quand ton téléphone bugue, tu demandes de l'aide à quelqu'un plutôt que de fouiller dans les réglages. | C9: Ta console ne se connecte pas au Wi-Fi : tu demandes à un proche de regarder. | D9: N | E9: N | F9: ? | G9: N | H9: O | I9: N | J9: O
A10: Q08 | B10: Quand tu as fini un travail, tu le rends sans forcément le relire. | C10: Ton devoir est terminé : tu le ranges dans ton sac sans y rejeter un œil. | D10: N | E10: O | F10: O | G10: ? | H10: O | I10: N | J10: N
A11: Q09 | B11: Répartir le travail du groupe, tu préfères le laisser à quelqu'un d'autre. | C11: Pour l'exposé, tu prends ta partie et tu laisses un autre suivre l'avancement. | D11: N | E11: O | F11: ? | G11: O | H11: N | I11: O | J11: N
A12: Q10 | B12: Que ton travail soit vu par tout le monde, ça t'importe peu. | C12: Ton dessin reste dans ton carnet : tu ne cherches pas à l'afficher. | D12: O | E12: ? | F12: N | G12: O | H12: N | I12: O | J12: N
A13: Q11 | B13: Tu aimes demander les goûts de chacun pour organiser une fête. | C13: Pour une fête de classe, tu fais un sondage sur le gâteau et la musique. | D13: N | E13: N | F13: ? | G13: N | H13: O | I13: N | J13: O
A14: Q12 | B14: En cuisine, tu suis la recette à la lettre et tu pèses tout. | C14: Pour un gâteau, tu mesures chaque ingrédient au gramme près. | D14: O | E14: N | F14: N | G14: ? | H14: N | I14: O | J14: O
... A52: Q50 | B52: Avant un départ, tu prépares ton sac au dernier moment. | C52: Le matin de la sortie scolaire, tu remplis ton sac juste avant de partir. | D52: N | E52: O | F52: O | G52: ? | H52: O | I52: N | J52: N

Sheet Métiers
A1: id | B1: nom | C1: salaire | D1: salaire_note | E1: dynamique | F1: dynamique_note | G1: cursus | H1: bacs | I1: etape1 | J1: detail1 | K1: etape2 | L1: detail2 | M1: etape3 | N1: detail3 | O1: etape_cible | P1: detail_cible | Q1: competences | R1: famille_principale | S1: famille_secondaire | T1: mission1 | U1: mission2 | V1: stage_3e | W1: entreprises_stage | X1: duree_etudes | Y1: qualites | Z1: matieres_terminale
B2: ex : Game Designer | C2: ex : 3 200 € | D2: ex : Évolution ultra-rapide | E2: ex : +18 % | F2: ex : Secteur porteur mondial | G2: ex : Bac +3/+5 | H2: ex : Générale ; STD2A ; STI2D | I2: ex : Collège 3ème | J2: ex : Stage découverte | K2: ex : Lycée Général | L2: ex : Spécialités Arts / NSI | M2: ex : École Sup / Master | N2: ex : Game Art & Design | O2: ex : Studio de Jeu | P2: ex : Game Designer | Q2: ex : Créativité ; Storytelling ; Logique | R2: ex : 4 – Data et IA | S2: ex : 3 – Design, développement, test et ops | T2: ex : Analyser les chiffres | U2: ex : Montrer les résultats | V2: ex : Équipe data d'une entreprise | W2: ex : Dataiku ; Criteo | X2: ex : 5 ans | Y2: ex : Esprit d'analyse et clarté | Z2: ex : Maths ; NSI ; Anglais
A3: M01 | B3: Développeur·se d'applications | C3: 33 – 40 k€ / an brut | D3: Ordre de grandeur, début de carrière, à confirmer (APEC, Opiiec, Onisep) | E3: À confirmer | F3: Source à identifier (Opiiec, APEC, France Travail) | G3: Bac +3/+5 | H3: Générale ; STI2D ; Pro Systèmes numériques | I3: Collège 3ème | J3: Maths, technologie, anglais | K3: Lycée | L3: Spécialité NSI ou maths / STI2D | M3: Études supérieures | N3: BTS SIO SLAM ; BUT Informatique ; école d'ingénieurs | O3: Entreprise du numérique | P3: Développeur·se d'applications | Q3: Résoudre avec méthode ; Créer et innover ; Apprendre à apprendre | R3: 3 – Design, développement, test et ops | S3: 2 – Robotique et objets connectés (IoT) | T3: Écrire le code des applications | U3: Corriger et améliorer le logiciel | V3: Équipe de développement ou studio de jeux vidéo | W3: Ubisoft ; Dassault Systèmes | X3: 3 à 5 ans | Y3: Logique et persévérance | Z3: Numérique et sciences informatiques (NSI) ; Mathématiques ; Anglais
A4: M02 | B4: Spécialiste robotique et automatisation | C4: 35 – 42 k€ / an brut | D4: Ordre de grandeur, début de carrière, à confirmer (APEC, Opiiec, Onisep) | E4: À confirmer | F4: Source à identifier (Opiiec, APEC, France Travail) | G4: Bac +5 | H4: Générale ; STI2D ; Pro Systèmes numériques | I4: Collège 3ème | J4: Technologie, maths, physique-chimie | K4: Lycée | L4: Spécialités maths, physique / STI2D | M4: Études supérieures | N4: BUT Génie électrique et info. industrielle ; école d'ingénieurs | O4: Entreprise de robotique | P4: Spécialiste robotique | Q4: Résoudre avec méthode ; Créer et innover ; Coopérer en équipe | R4: 2 – Robotique et objets connectés (IoT) | S4: 3 – Design, développement, test et ops | T4: Concevoir et monter des robots | U4: Programmer leurs mouvements | V4: Atelier de robotique ou bureau d'études | W4: Schneider Electric ; Naval Group | X4: 5 ans | Y4: Esprit pratique et minutie | Z4: Mathématiques ; Physique-chimie ; Sciences de l'ingénieur
A5: M03 | B5: Expert·e en intelligence artificielle | C5: 42 – 55 k€ / an brut | D5: Ordre de grandeur, début de carrière, à confirmer (APEC, Opiiec, Onisep) | E5: À confirmer | F5: Source à identifier (Opiiec, APEC, France Travail) | G5: Bac +5 | H5: Générale ; STI2D | I5: Collège 3ème | J5: Maths, physique-chimie, technologie | K5: Lycée | L5: Spécialités maths et NSI | M5: Études supérieures | N5: BUT Science des données ; licence puis master ; école d'ingénieurs | O5: Laboratoire ou entreprise d'IA | P5: Expert·e en IA | Q5: Analyser et raisonner ; Apprendre à apprendre ; Créer et innover | R5: 4 – Data et IA | S5: 3 – Design, développement, test et ops | T5: Entraîner des programmes intelligents | U5: Vérifier qu'ils ne se trompent pas | V5: Équipe data ou IA d'une entreprise | W5: Dataiku ; Criteo | X5: 5 ans | Y5: Curiosité et esprit d'analyse | Z5: Mathématiques ; NSI ; Anglais
A6: M04 | B6: Développeur·se back-end | C6: 35 – 42 k€ / an brut | D6: Ordre de grandeur, début de carrière, à confirmer (APEC, Opiiec, Onisep) | E6: À confirmer | F6: Source à identifier (Opiiec, APEC, France Travail) | G6: Bac +3/+5 | H6: Générale ; STI2D ; Pro Systèmes numériques | I6: Collège 3ème | J6: Maths, technologie, anglais | K6: Lycée | L6: Spécialité NSI ou maths / STI2D | M6: Études supérieures | N6: BTS SIO SLAM ; BUT Informatique ; école d'ingénieurs | O6: Entreprise du numérique | P6: Développeur·se back-end | Q6: Résoudre avec méthode ; Coopérer en équipe ; Analyser et raisonner | R6: 3 – Design, développement, test et ops | S6: 1 – Infrastructures, cloud et réseaux | T6: Programmer serveurs et bases de données | U6: Faire communiquer les applications | V6: Équipe de développement d'une application connue | W6: Doctolib ; Sopra Steria | X6: 3 à 5 ans | Y6: Logique et rigueur | Z6: NSI ; Mathématiques ; Anglais
A7: M05 | B7: Data scientist | C7: 40 – 50 k€ / an brut | D7: Ordre de grandeur, début de carrière, à confirmer (APEC, Opiiec, Onisep) | E7: À confirmer | F7: Source à identifier (Opiiec, APEC, France Travail) | G7: Bac +5 | H7: Générale ; STI2D | I7: Collège 3ème | J7: Maths, histoire-géo, technologie | K7: Lycée | L7: Spécialités maths et NSI | M7: Études supérieures | N7: BUT Science des données ; licence puis master ; école d'ingénieurs | O7: Équipe données d'une entreprise | P7: Data scientist | Q7: Analyser et raisonner ; Communiquer et expliquer ; Résoudre avec méthode | R7: 4 – Data et IA | S7: 7 – Stratégie et gestion de projet | T7: Analyser les chiffres et les données | U7: Montrer les résultats en graphiques | V7: Équipe data ou études statistiques | W7: Criteo ; Orange | X7: 5 ans | Y7: Esprit d'analyse et clarté | Z7: Mathématiques ; NSI ; Sciences économiques et sociales (SES)
A8: M06 | B8: Testeur·se et ingénieur·e qualité | C8: 32 – 38 k€ / an brut | D8: Ordre de grandeur, début de carrière, à confirmer (APEC, Opiiec, Onisep) | E8: À confirmer | F8: Source à identifier (Opiiec, APEC, France Travail) | G8: Bac +2/+5 | H8: Générale ; STI2D ; Pro Systèmes numériques | I8: Collège 3ème | J8: Maths, technologie, français | K8: Lycée | L8: Spécialité NSI ou maths / STI2D | M8: Études supérieures | N8: BTS SIO ; BUT Informatique ; formations en test logiciel | O8: Équipe qualité d'un éditeur de logiciels | P8: Testeur·se qualité | Q8: Analyser et raisonner ; Coopérer en équipe ; Communiquer et expliquer | R8: 3 – Design, développement, test et ops | S8: 6 – Cybersécurité et sûreté des systèmes d'information | T8: Tester les logiciels avant leur sortie | U8: Signaler et suivre les bugs | V8: Équipe qualité d'un éditeur de logiciels ou de jeux | W8: Capgemini ; Ubisoft | X8: 2 à 5 ans | Y8: Minutie et patience | Z8: NSI ; Mathématiques ; Anglais
A9: M07 | B9: Pentesteur·se / analyste cybersécurité | C9: 38 – 48 k€ / an brut | D9: Ordre de grandeur, début de carrière, à confirmer (APEC, Opiiec, Onisep) | E9: À confirmer | F9: Source à identifier (Opiiec, APEC, France Travail) | G9: Bac +3/+5 | H9: Générale ; STI2D ; Pro Systèmes numériques | I9: Collège 3ème | J9: Maths, technologie, anglais | K9: Lycée | L9: Spécialité NSI ou maths / STI2D | M9: Études supérieures | N9: BTS CIEL ; BUT Réseaux et télécoms (cybersécurité) ; école d'ingénieurs | O9: Cabinet ou équipe cybersécurité | P9: Pentesteur·se | Q9: Analyser et raisonner ; Résoudre avec méthode ; Apprendre à apprendre | R9: 6 – Cybersécurité et sûreté des systèmes d'information | S9: 1 – Infrastructures, cloud et réseaux | T9: Chercher les failles d'un système | U9: Expliquer comment les corriger | V9: Équipe sécurité informatique | W9: Orange Cyberdefense ; Thales | X9: 3 à 5 ans | Y9: Ruse et éthique | Z9: NSI ; Mathématiques ; Anglais
A10: M08 | B10: Spécialiste systèmes, réseaux et cloud | C10: 33 – 40 k€ / an brut | D10: Ordre de grandeur, début de carrière, à confirmer (APEC, Opiiec, Onisep) | E10: À confirmer | F10: Source à identifier (Opiiec, APEC, France Travail) | G10: Bac +2/+5 | H10: Pro Systèmes numériques ; STI2D ; Générale | I10: Collège 3ème | J10: Maths, technologie, physique-chimie | K10: Lycée | L10: STI2D ou spécialité NSI / Pro Systèmes numériques | M10: Études supérieures | N10: BTS SIO SISR ; BUT Réseaux et télécoms ; école d'ingénieurs | O10: Opérateur réseau ou service informatique | P10: Spécialiste systèmes et réseaux | Q10: Résoudre avec méthode ; Coopérer en équipe ; S'adapter et rebondir | R10: 1 – Infrastructures, cloud et réseaux | S10: 6 – Cybersécurité et sûreté des systèmes d'information | T10: Installer réseaux, serveurs et cloud | U10: Surveiller que tout fonctionne | V10: Salle serveurs ou service informatique | W10: OVHcloud ; Orange | X10: 2 à 5 ans | Y10: Rigueur et sang-froid | Z10: NSI ; Mathématiques ; Physique-chimie
A11: M09 | B11: UX / UI designer | C11: 32 – 40 k€ / an brut | D11: Ordre de grandeur, début de carrière, à confirmer (APEC, Opiiec, Onisep) | E11: À confirmer | F11: Source à identifier (Opiiec, APEC, France Travail) | G11: Bac +3/+5 | H11: Générale ; STD2A ; STI2D | I11: Collège 3ème | J11: Arts plastiques, français, technologie | K11: Lycée | L11: Spécialité arts / STD2A | M11: Études supérieures | N11: BUT Métiers du multimédia ; DN MADE numérique ; école de design | O11: Agence ou studio de design | P11: UX / UI designer | Q11: Créer et innover ; Communiquer et expliquer ; Apprendre à apprendre | R11: 3 – Design, développement, test et ops | S11: 5 – Marketing digital, communication et e-commerce | T11: Dessiner des écrans simples à utiliser | U11: Tester avec de vrais utilisateurs | V11: Studio de design ou agence web | W11: Doctolib ; Publicis | X11: 3 à 5 ans | Y11: Créativité et sens de l'écoute | Z11: Arts plastiques ; Humanités, littérature et philosophie (HLP) ; Anglais
A12: M10 | B12: Community manager | C12: 27 – 33 k€ / an brut | D12: Ordre de grandeur, début de carrière, à confirmer (APEC, Opiiec, Onisep) | E12: À confirmer | F12: Source à identifier (Opiiec, APEC, France Travail) | G12: Bac +3/+5 | H12: Générale ; STMG ; Pro | I12: Collège 3ème | J12: Français, anglais, arts plastiques | K12: Lycée | L12: Spécialité langues ou humanités | M12: Études supérieures | N12: BUT Information-communication ou MMI ; licence info-com | O12: Marque, agence ou studio de jeu | P12: Community manager | Q12: Communiquer et expliquer ; Créer et innover ; S'adapter et rebondir | R12: 5 – Marketing digital, communication et e-commerce | S12: 7 – Stratégie et gestion de projet | T12: Animer les réseaux sociaux | U12: Répondre à la communauté | V12: Agence de communication ou service communication | W12: Havas ; Publicis | X12: 3 à 5 ans | Y12: Dynamisme et sens du contact | Z12: Anglais ; Humanités, littérature et philosophie (HLP) ; Sciences économiques et sociales (SES)
A13: M11 | B13: Responsable Green IT / éco-conception | C13: 36 – 45 k€ / an brut | D13: Ordre de grandeur, début de carrière, à confirmer (APEC, Opiiec, Onisep) | E13: À confirmer | F13: Source à identifier (Opiiec, APEC, France Travail) | G13: Bac +5 | H13: Générale ; STI2D | I13: Collège 3ème | J13: SVT, technologie, physique-chimie | K13: Lycée | L13: Spécialités SVT, physique-chimie ou NSI / STI2D | M13: Études supérieures | N13: BUT Informatique ou Génie industriel ; école d'ingénieurs (numérique responsable) | O13: Entreprise ou collectivité | P13: Responsable Green IT | Q13: Analyser et raisonner ; Se connaître et s'engager ; Communiquer et expliquer | R13: 1 – Infrastructures, cloud et réseaux | S13: 7 – Stratégie et gestion de projet | T13: Réduire l'énergie du numérique | U13: Concevoir des services plus sobres | V13: Équipe numérique responsable d'un grand groupe | W13: Capgemini ; Orange | X13: 5 ans | Y13: Conscience écologique et esprit de synthèse | Z13: SVT ; Physique-chimie ; NSI
A14: M12 | B14: Ingénieur·e e-santé | C14: 36 – 45 k€ / an brut | D14: Ordre de grandeur, début de carrière, à confirmer (APEC, Opiiec, Onisep) | E14: À confirmer | F14: Source à identifier (Opiiec, APEC, France Travail) | G14: Bac +5 | H14: Générale ; STI2D | I14: Collège 3ème | J14: SVT, maths, technologie | K14: Lycée | L14: Spécialités SVT, maths ou NSI | M14: Études supérieures | N14: BUT Informatique ou GEII ; école d'ingénieurs (santé) ; master informatique de santé | O14: Hôpital ou entreprise de santé numérique | P14: Ingénieur·e e-santé | Q14: Coopérer en équipe ; Communiquer et expliquer ; Se connaître et s'engager | R14: 4 – Data et IA | S14: 2 – Robotique et objets connectés (IoT) | T14: Créer des outils numériques pour la santé | U14: Protéger les données des patients | V14: Équipe numérique d'un hôpital ou d'une entreprise de santé | W14: Doctolib ; Sanofi | X14: 5 ans | Y14: Empathie et rigueur | Z14: SVT ; Mathématiques ; NSI
... A18: M16 | B18: Chef·fe de projet digital | C18: 38 – 48 k€ / an brut | D18: Ordre de grandeur, début de carrière, à confirmer (APEC, Opiiec, Onisep) | E18: À confirmer | F18: Source à identifier (Opiiec, APEC, France Travail) | G18: Bac +5 | H18: Générale ; STMG ; STI2D | I18: Collège 3ème | J18: Maths, français, anglais | K18: Lycée | L18: Spécialités maths, langues ou économie | M18: Études supérieures | N18: BUT ou licence puis master ; école d'ingénieurs ou de commerce | O18: Agence ou direction de projet numérique | P18: Chef·fe de projet digital | Q18: Coopérer en équipe ; Communiquer et expliquer ; Résoudre avec méthode | R18: 7 – Stratégie et gestion de projet | S18: 3 – Design, développement, test et ops | T18: Diriger et organiser les projets | U18: Tenir les délais et le budget | V18: Chef de projet dans une entreprise de services numériques | W18: Capgemini ; Sopra Steria | X18: 5 ans | Y18: Leadership et sens de l'organisation | Z18: Mathématiques ; Sciences économiques et sociales (SES) ; Anglais

Sheet Familles
A1: id | B1: nom | C1: domaines | D1: cursus | E1: bacs | F1: mission1 | G1: mission2 | H1: matieres_indispensables | I1: matieres_souhaitables | J1: stage_3e | K1: entreprises_stage | L1: qualites | M1: metiers_principaux | N1: metiers_voisins
B2: ex : Data et IA | C2: ex : Analyse des données ; ingénierie des données | D2: ex : Bac +3/+5 : BUT Science des données, master | E2: ex : Générale (Maths + NSI) | F2: ex : Analyser les chiffres et les données | G2: ex : Entraîner des programmes à prévoir | H2: ex : Mathématiques ; NSI | I2: ex : Anglais ; SES | J2: ex : Équipe data d'une entreprise | K2: ex : Dataiku ; Criteo | L2: ex : Esprit d'analyse et curiosité | M2: ex : Data scientist | N2: ex : Ingénieur·e e-santé
A3: F01 | B3: Infrastructures, cloud et réseaux | C3: Systèmes, réseaux et serveurs ; datacenter ; cloud ; maintien en condition opérationnelle et assistance | D3: Bac général (spécialités Maths + NSI ou Physique-chimie), bac STI2D ou bac pro Systèmes numériques → BTS SIO option SISR, BTS CIEL ou BUT Réseaux et télécommunications → licence pro ou école d'ingénieurs. | E3: Générale (Maths + NSI ou Physique-chimie) ; STI2D ; Pro Systèmes numériques | F3: Faire fonctionner réseaux et serveurs | G3: Dépanner et assister les utilisateurs | H3: Mathématiques ; Numérique et sciences informatiques (NSI) | I3: Physique-chimie ; Anglais ; Technologie | J3: Observer l'équipe informatique d'une entreprise ou d'une mairie : câblage, serveurs, dépannage | K3: Orange ; OVHcloud | L3: Logique et sens du service | M3: Spécialiste systèmes, réseaux et cloud (TFCK) ; Responsable Green IT / éco-conception (HICE) ; Technicien·ne informatique (HFVE) | N3: Développeur·se back-end (TICK) ; Pentesteur·se / analyste cybersécurité (TFCE)
A4: F02 | B4: Robotique et objets connectés (IoT) | C4: Écosystèmes connectés ; systèmes embarqués | D4: Bac STI2D (SIN ou ITEC) ou bac général (Maths + Physique-chimie + NSI) → BUT Génie électrique et informatique industrielle ou BUT Mesures physiques → école d'ingénieurs (électronique, systèmes embarqués) ou classe prépa. | E4: STI2D ; Générale (Maths + Physique-chimie + NSI) | F4: Concevoir des objets connectés | G4: Programmer les objets intelligents | H4: Mathématiques ; Physique-chimie ; Sciences de l'ingénieur ou NSI | I4: Anglais ; Technologie ; Arts plastiques | J4: Atelier de robotique ou d'électronique, bureau d'études | K4: Thales ; Schneider Electric | L4: Curiosité et esprit d'invention | M4: Spécialiste robotique et automatisation (TIVK) | N4: Développeur·se d'applications (TIVE) ; Ingénieur·e e-santé (HICK)
A5: F03 | B5: Design, développement, test et ops | C5: Jumeau numérique / BIM ; UX et design ; analyse, ingénierie et développement ; qualité, test, homologation ; DevOps et industrialisation | D5: Bac général (Maths + NSI), bac STI2D ou bac STD2A pour le design → BUT Informatique, BTS SIO option SLAM, BUT Métiers du multimédia et de l'internet ou DN MADE numérique → licence, master ou école d'ingénieurs. | E5: Générale (Maths + NSI) ; STI2D ; STD2A | F5: Créer des applications faciles à utiliser | G5: Tester pour supprimer les bugs | H5: Mathématiques ; NSI (ou Arts plastiques pour le design) | I5: Anglais ; Français ; Arts plastiques | J5: Équipe de développement, studio de jeux vidéo ou agence web | K5: Ubisoft ; Dassault Systèmes | L5: Créativité et persévérance | M5: Développeur·se d'applications (TIVE) ; Développeur·se back-end (TICK) ; Testeur·se et ingénieur·e qualité (TFVK) ; UX / UI designer (HIVE) | N5: Spécialiste robotique et automatisation (TIVK) ; Expert·e en intelligence artificielle (TICE) ; Chef·fe de projet digital (HFCK)
A6: F04 | B6: Data et IA | C6: Ingénierie des données ; analyse des données et IA ; informatique décisionnelle | D6: Bac général (Maths + NSI ou Physique-chimie) → BUT Science des données ou licence Maths-Informatique → master Data/IA ou école d'ingénieurs. | E6: Générale (Maths + NSI ou Physique-chimie) | F6: Analyser les chiffres et les données | G6: Entraîner des programmes à prévoir | H6: Mathématiques ; NSI | I6: Anglais ; Physique-chimie ; Sciences économiques et sociales ; Français | J6: Équipe data d'une entreprise ou d'une administration | K6: Dataiku ; Criteo | L6: Esprit d'analyse et curiosité | M6: Expert·e en intelligence artificielle (TICE) ; Data scientist (TFVE) ; Ingénieur·e e-santé (HICK)
A7: F05 | B7: Marketing digital, communication et e-commerce | C7: E-commerce ; acquisition de trafic et visibilité ; marketing digital ; médias sociaux et influence ; relation client | D7: Bac général (SES, HLP, Anglais renforcé) ou bac STMG → BUT Métiers du multimédia et de l'internet, BUT Techniques de commercialisation ou BTS Communication → licence, master ou école de commerce ou de communication. | E7: Générale (SES, HLP, Anglais) ; STMG | F7: Vendre et communiquer sur internet | G7: Écouter et fidéliser les clients | H7: Français ; Anglais | I7: Sciences économiques et sociales ; Arts plastiques ; Mathématiques | J7: Agence de communication ou service e-commerce | K7: Publicis ; Havas | L7: Dynamisme et sens du contact | M7: Community manager (HIVK) ; Technico-commercial·e tech (HFVK) | N7: UX / UI designer (HIVE) ; Technicien·ne informatique (HFVE)
A8: F06 | B8: Cybersécurité et sûreté des systèmes d'information | C8: Gouvernance, risques et conformité ; ingénierie et sécurisation ; défense opérationnelle ; audit et évaluation | D8: Bac général (Maths + NSI), bac STI2D ou bac pro Systèmes numériques → BTS CIEL, BUT Réseaux et télécommunications parcours cybersécurité → licence pro, master cyber ou école d'ingénieurs. | E8: Générale (Maths + NSI) ; STI2D ; Pro Systèmes numériques | F8: Protéger les données des pirates | G8: Détecter les attaques et réparer | H8: Mathématiques ; NSI | I8: Anglais ; Physique-chimie ; Histoire-géographie, géopolitique et sciences politiques | J8: Équipe sécurité informatique d'un grand groupe | K8: Orange Cyberdefense ; Airbus | L8: Rigueur et vigilance | M8: Pentesteur·se / analyste cybersécurité (TFCE) ; Délégué·e à la protection des données (DPO) (HFCE) | N8: Testeur·se et ingénieur·e qualité (TFVK) ; Spécialiste systèmes, réseaux et cloud (TFCK)
A9: F07 | B9: Stratégie et gestion de projet | C9: Direction et gouvernance ; pilotage de projets et PMO ; pilotage produit et agilité ; expertise fonctionnelle | D9: Bac général (Maths, SES, HGGSP, Anglais) ou bac STMG → BUT Informatique, Gestion des entreprises ou Techniques de commercialisation → licence puis master, école d'ingénieurs ou de commerce. | E9: Générale (Maths, SES, HGGSP) ; STMG | F9: Diriger et organiser les projets | G9: Tenir les délais et le budget | H9: Français ; Mathématiques | I9: Anglais ; Sciences économiques et sociales ; Histoire-géographie, géopolitique et sciences politiques | J9: Chef de projet dans une entreprise de services numériques | K9: Capgemini ; Sopra Steria | L9: Leadership et sens de l'organisation | M9: Chef·fe de projet digital (HFCK) | N9: Data scientist (TFVE) ; Community manager (HIVK) ; Responsable Green IT / éco-conception (HICE) ; Technico-commercial·e tech (HFVK) ; Délégué·e à la protection des données (DPO) (HFCE)

Sheet Pôles visés
A1: id | B1: axe | C1: pôle visé | D1: décisive | E1: ligne d'origine (matrice enrichie) | G1: Légende : H = personnes, T = technique ; I = improviser, F = préparer ; V = côté visible, C = coulisses ; E = expertise, K = collectif.
A2: Q01 | B2: 2 | C2: F | E2: 10
A3: Q02 | B3: 3 | C3: C | E3: 30
A4: Q03 | B4: 1 | C4: T | E4: 2
A5: Q04 | B5: 4 | C5: K | E5: 43
A6: Q05 | B6: 2 | C6: I | D6: Oui | E6: 16
A7: Q06 | B7: 3 | C7: V | E7: 36
A8: Q07 | B8: 1 | C8: H | E8: 6
A9: Q08 | B9: 2 | C9: I | E9: 11
A10: Q09 | B10: 4 | C10: E | E10: 48
A11: Q10 | B11: 3 | C11: C | E11: 31
A12: Q11 | B12: 1 | C12: H | E12: 3
A13: Q12 | B13: 2 | C13: F | E13: 17
A14: Q13 | B14: 3 | C14: V | E14: 37
A15: Q14 | B15: 4 | C15: E | D15: Oui | E15: 44
A16: Q15 | B16: 2 | C16: I | E16: 22
A17: Q16 | B17: 1 | C17: T | E17: 7
A18: Q17 | B18: 2 | C18: I | E18: 18
A19: Q18 | B19: 3 | C19: V | E19: 32
A20: Q19 | B20: 1 | C20: T | E20: 4
A21: Q20 | B21: 4 | C21: E | E21: 49
A22: Q21 | B22: 2 | C22: F | E22: 23
A23: Q22 | B23: 3 | C23: C | E23: 38
A24: Q23 | B24: 1 | C24: T | D24: Oui | E24: 8
A25: Q24 | B25: 2 | C25: I | E25: 19
A26: Q25 | B26: 3 | C26: C | D26: Oui | E26: 33
A27: Q26 | B27: 4 | C27: E | E27: 45
A28: Q27 | B28: 2 | C28: I | E28: 24
A29: Q28 | B29: 1 | C29: H | E29: 5
A30: Q29 | B30: 3 | C30: V | D30: Oui | E30: 39
A31: Q30 | B31: 2 | C31: F | D31: Oui | E31: 25
A32: Q31 | B32: 4 | C32: K | D32: Oui | E32: 50
A33: Q32 | B33: 1 | C33: H | D33: Oui | E33: 9
A34: Q33 | B34: 3 | C34: C | E34: 34
A35: Q34 | B35: 2 | C35: F | E35: 20
A36: Q35 | B36: 1 | C36: H | E36: 12
A37: Q36 | B37: 2 | C37: I | E37: 26
A38: Q37 | B38: 4 | C38: K | E38: 46
A39: Q38 | B39: 3 | C39: C | E39: 40
A40: Q39 | B40: 2 | C40: I | E40: 21
...

Sheet Inversions V6
A1: id | B1: ancienne affirmation | C1: nouvelle affirmation | D1: ancien exemple | E1: nouvel exemple | F1: ancien pôle | G1: nouveau pôle
A2: Q02 | B2: Tu aimes animer un spectacle sur scène. | C2: Monter sur scène devant un public, ça te met mal à l'aise. | D2: Tu te portes volontaire pour présenter le spectacle de fin d'année. | E2: Pour le spectacle de fin d'année, tu préfères aider en coulisses que présenter. | F2: V | G2: C
A3: Q03 | B3: Tu aimes demander l'avis de chacun avant de te lancer dans un travail de groupe. | C3: En travail de groupe, tu te lances directement dans les recherches sans demander l'avis de chacun. | D3: En travail de groupe, tu demandes à chacun si le sujet lui plaît avant de chercher. | E3: Le sujet est donné : tu ouvres tout de suite l'ordinateur pour chercher des infos. | F3: H | G3: T
A4: Q04 | B4: Tu aimes t'entraîner des heures pour devenir le ou la meilleur(e). | C4: T'entraîner des heures seul(e) pour devenir le ou la meilleur(e), ça te lasse vite. | D4: Tu répètes le même morceau de guitare jusqu'à ce que chaque note soit parfaite. | E4: Répéter seul(e) le même morceau de guitare, tu décroches au bout d'un moment. | F4: E | G4: K
A5: Q06 | B5: Tu aimes gérer le son ou la lumière dans l'ombre d'un spectacle. | C5: Pendant un spectacle, tu préfères être sur scène plutôt qu'à la régie son et lumière. | D5: Au spectacle du collège, tu gères la musique depuis le fond de la salle. | E5: Au spectacle du collège, tu veux être sous les projecteurs, pas au fond de la salle. | F5: C | G5: V
A6: Q07 | B6: Quand ton téléphone ou ton ordinateur bugue, tu aimes fouiller dans les réglages. | C6: Quand ton téléphone bugue, tu demandes de l'aide à quelqu'un plutôt que de fouiller dans les réglages. | D6: Ta console ne se connecte pas au Wi-Fi : tu cherches dans les réglages jusqu'au bout. | E6: Ta console ne se connecte pas au Wi-Fi : tu demandes à un proche de regarder. | F6: T | G6: H
A7: Q08 | B7: Tu aimes relire un texte mot à mot pour traquer la moindre faute. | C7: Quand tu as fini un travail, tu le rends sans forcément le relire. | D7: Ton devoir est fini : tu relis chaque ligne avec une règle pour traquer les fautes. | E7: Ton devoir est terminé : tu le ranges dans ton sac sans y rejeter un œil. | F7: F | G7: I
A8: Q09 | B8: Tu aimes répartir le travail et vérifier que chacun avance. | C8: Répartir le travail du groupe, tu préfères le laisser à quelqu'un d'autre. | D8: Tu crées un groupe de discussion pour demander à chacun où il en est de l'exposé. | E8: Pour l'exposé, tu prends ta partie et tu laisses un autre suivre l'avancement. | F8: K | G8: E
A9: Q10 | B9: Tu aimes créer quelque chose de beau que tout le monde verra. | C9: Que ton travail soit vu par tout le monde, ça t'importe peu. | D9: Tu passes des heures sur l'affiche du journal du collège, vue par tous. | E9: Ton dessin reste dans ton carnet : tu ne cherches pas à l'afficher. | F9: V | G9: C
A10: Q12 | B10: Tu aimes tester des mélanges au hasard sans suivre de recette. | C10: En cuisine, tu suis la recette à la lettre et tu pèses tout. | D10: Tu fais un gâteau en remplaçant le sucre par du miel, sans rien peser. | E10: Pour un gâteau, tu mesures chaque ingrédient au gramme près. | F10: I | G10: F
A11: Q13 | B11: Tu aimes préparer discrètement le matériel pour les autres. | C11: Préparer le matériel dans l'ombre pour les autres, ça t'ennuie un peu. | D11: Avant l'entraînement, tu vérifies que ballons et chasubles sont dans le sac. | E11: Avant l'entraînement, tu laisses les autres préparer ballons et chasubles. | F11: C | G11: V
A12: Q15 | B12: Avant de rendre un travail, tu vérifies plusieurs fois tes résultats. | C12: Quand tu as trouvé un résultat, tu passes à la suite sans le revérifier. | D12: Tu refais tes calculs de maths sur un brouillon pour être sûr(e). | E12: Ton calcul de maths est fini : tu passes directement à l'exercice suivant. | F12: F | G12: I
... A26: Q50 | B26: Avant un départ, tu vérifies deux fois ton sac. | C26: Avant un départ, tu prépares ton sac au dernier moment. | D26: La veille d'une sortie scolaire, tu revérifies ton sac plusieurs fois. | E26: Le matin de la sortie scolaire, tu remplis ton sac juste avant de partir. | F26: F | G26: I
