Workbook

Sheet Lisez-moi
A1: Orien Tech' V1 : 32 affirmations « C'est… que tu… » Oui / Non pour 16 métiers
A3: Ce qui change | B3: Toutes les affirmations suivent le modèle « C'est quand / en… que tu donnes le meilleur de toi (ou produis les meilleurs résultats, ou te sens le plus à l'aise) ». Chaque affirmation décrit où le joueur est à son meilleur, ce qui valorise aussi bien un Oui qu'un Non. Aucune ne décrit une qualité ou un défaut d'élève.
A4: Consigne à donner au joueur | B4: « Il n'y a ni bonne ni mauvaise réponse. Réponds Oui si c'est vrai pour toi, Non si ce n'est pas vraiment ton cas. »
A5: Mise en situation illustrative | B5: Chaque affirmation est suivie d'un exemple concret de la vie de collégien, pour que le joueur comprenne bien la question. L'exemple illustre l'affirmation : il ne change pas la réponse attendue (Oui si c'est vrai pour toi, Non sinon). Dans l'application, il peut s'afficher sous la question ou à la demande.
A6: Principe | B6: 4 axes à deux pôles, 2⁴ = 16 profils, un code de 4 lettres = un métier. Chaque axe a 8 questions : 4 qui décrivent le pôle 1 et 4 qui décrivent le pôle 2.
A7: Comment on compte | B7: Un Oui ajoute 1 point au pôle visé par la question. Un Non n'ajoute rien : il ne veut pas dire qu'on est l'inverse, juste que ça ne te ressemble pas. Pour chaque axe, le pôle qui a le plus de Oui l'emporte (score de 0 à 4).
A8: Égalité | B8: En cas d'égalité (par exemple 2-2), une question décisive par axe (colonne Décisive = Oui) tranche : Oui à cette question donne son pôle, Non donne l'autre pôle.
A9: Réponses peu utiles | B9: Si le joueur répond Oui (ou Non) presque partout, la feuille Test affiche un avertissement : le résultat est alors peu fiable.
A10: Ordre de passation | B10: Les axes alternent d'une question à l'autre, et les pôles aussi, pour que le joueur ne devine pas ce qui est mesuré.
A11: Lien avec les axes | B11: Chaque affirmation décrit un contexte où le joueur est à son meilleur, ce qui oriente vers un pôle. Exemples : « à la dernière minute » oriente vers Improviser ; « quand tu as pu tout préparer à l'avance » vers Préparer ; « en t'occupant de la sono » vers Technique. Ce sont mes lectures, à discuter et à tester.
A12: Limites | B12: Les questions n'ont pas été essayées avec des élèves de 4ᵉ. Plusieurs Oui sont probables (on aime tout un peu à 14 ans) : le test doit montrer si les scores se différencient assez. Les codes de 4 lettres rattachés aux métiers sont mon choix, à valider.
A13: Légende | B13: Fond jaune et texte bleu : réponses à saisir (Oui ou Non). Les réponses présentes sont un exemple (profil HIVE) à remplacer.
A14: Matrice (nouvel onglet) | B14: Une ligne par affirmation (modèle de la matrice d'orientation vers les familles de métiers) : axe, pôles, ce que mesure l'axe, compétences, question équivalente, mise en situation, pôle visé si Oui / si Non, familles et métiers associés au pôle.
... A16: Attention | B16: Rattachements pôle → familles et métier → famille = propositions de travail, à valider avec l'équipe et un conseiller d'orientation.

Sheet Test
A1: N° | B1: Axe | C1: Mise en situation | D1: Oui ou Non | E1: Pôle visé | F1: Décisive (axe) | H1: Axe | I1: Nom | J1: Pôle 1 | K1: Oui pôle 1 | L1: Pôle 2 | M1: Oui pôle 2 | N1: Pôle retenu
A2: =Questions!A2 -> 1 | B2: =Questions!B2 -> 1 | C2: =Questions!D2&CHAR(10)&Questions!G2 -> C'est en accueillant les invités d'une fête, en veillant à ce que chacun se sente bien, que tu donnes le meilleur de toi. Exemple : pour l'anniversaire de ton meilleur ami, tu es à la porte, tu salues chaque invité, tu présentes ceux qui ne se connaissent pas et tu veilles à ce que personne ne reste seul dans son coin. | D2: Oui | E2: =Questions!E2 -> H | F2: =IF(Questions!F2="Oui",B2,"") | H2: 1 | I2: =Axes!B2 -> Ce qui m'attire | J2: =Axes!D2 -> H | K2: =COUNTIFS($B$2:$B$33,H2,$E$2:$E$33,J2,$D$2:$D$33,"Oui") -> 4 | L2: =Axes!F2 -> T | M2: =COUNTIFS($B$2:$B$33,H2,$E$2:$E$33,L2,$D$2:$D$33,"Oui") -> 0 | N2: =IF(COUNTA($D$2:$D$33)<32,"?",IF(K2>M2,J2,IF(M2>K2,L2,IF(INDEX($D$2:$D$33,MATCH(H2,$F$2:$F$33,0))="Oui",INDEX($E$2:$E$33,MATCH(H2,$F$2:$F$33,0)),IF(INDEX($E$2:$E$33,MATCH(H2,$F$2:$F$33,0))=J2,L2,J2))))) -> H
A3: =Questions!A3 -> 2 | B3: =Questions!B3 -> 2 | C3: =Questions!D3&CHAR(10)&Questions!G3 -> C'est quand un prof te laisse choisir librement comment présenter ton travail que tu produis tes meilleurs résultats. Exemple : le prof dit « Présentez ce thème comme vous voulez : affiche, vidéo, saynète… ». Tu choisis ton format et tu te lances. | D3: Oui | E3: =Questions!E3 -> I | F3: =IF(Questions!F3="Oui",B3,"") | H3: 2 | I3: =Axes!B3 -> Ma démarche | J3: =Axes!D3 -> I | K3: =COUNTIFS($B$2:$B$33,H3,$E$2:$E$33,J3,$D$2:$D$33,"Oui") -> 4 | L3: =Axes!F3 -> F | M3: =COUNTIFS($B$2:$B$33,H3,$E$2:$E$33,L3,$D$2:$D$33,"Oui") -> 0 | N3: =IF(COUNTA($D$2:$D$33)<32,"?",IF(K3>M3,J3,IF(M3>K3,L3,IF(INDEX($D$2:$D$33,MATCH(H3,$F$2:$F$33,0))="Oui",INDEX($E$2:$E$33,MATCH(H3,$F$2:$F$33,0)),IF(INDEX($E$2:$E$33,MATCH(H3,$F$2:$F$33,0))=J3,L3,J3))))) -> I
A4: =Questions!A4 -> 3 | B4: =Questions!B4 -> 3 | C4: =Questions!D4&CHAR(10)&Questions!G4 -> C'est quand tu présentes ton travail devant la classe que tu donnes le meilleur de toi. Exemple : ton groupe a fini son exposé et tu te lèves devant la classe pour le présenter. | D4: Oui | E4: =Questions!E4 -> V | F4: =IF(Questions!F4="Oui",B4,"") | H4: 3 | I4: =Axes!B4 -> Mon terrain | J4: =Axes!D4 -> V | K4: =COUNTIFS($B$2:$B$33,H4,$E$2:$E$33,J4,$D$2:$D$33,"Oui") -> 4 | L4: =Axes!F4 -> C | M4: =COUNTIFS($B$2:$B$33,H4,$E$2:$E$33,L4,$D$2:$D$33,"Oui") -> 0 | N4: =IF(COUNTA($D$2:$D$33)<32,"?",IF(K4>M4,J4,IF(M4>K4,L4,IF(INDEX($D$2:$D$33,MATCH(H4,$F$2:$F$33,0))="Oui",INDEX($E$2:$E$33,MATCH(H4,$F$2:$F$33,0)),IF(INDEX($E$2:$E$33,MATCH(H4,$F$2:$F$33,0))=J4,L4,J4))))) -> V
A5: =Questions!A5 -> 4 | B5: =Questions!B5 -> 4 | C5: =Questions!D5&CHAR(10)&Questions!G5 -> C'est quand tu apprends seul(e) que tu retiens le mieux. Exemple : tu veux apprendre une nouvelle technique de dessin ou un nouveau tour de magie. Tu regardes un tutoriel et tu t'entraînes seul(e) jusqu'à y arriver. | D5: Oui | E5: =Questions!E5 -> E | F5: =IF(Questions!F5="Oui",B5,"") | H5: 4 | I5: =Axes!B5 -> Ma façon de travailler | J5: =Axes!D5 -> E | K5: =COUNTIFS($B$2:$B$33,H5,$E$2:$E$33,J5,$D$2:$D$33,"Oui") -> 4 | L5: =Axes!F5 -> K | M5: =COUNTIFS($B$2:$B$33,H5,$E$2:$E$33,L5,$D$2:$D$33,"Oui") -> 0 | N5: =IF(COUNTA($D$2:$D$33)<32,"?",IF(K5>M5,J5,IF(M5>K5,L5,IF(INDEX($D$2:$D$33,MATCH(H5,$F$2:$F$33,0))="Oui",INDEX($E$2:$E$33,MATCH(H5,$F$2:$F$33,0)),IF(INDEX($E$2:$E$33,MATCH(H5,$F$2:$F$33,0))=J5,L5,J5))))) -> E
A6: =Questions!A6 -> 5 | B6: =Questions!B6 -> 1 | C6: =Questions!D6&CHAR(10)&Questions!G6 -> C'est en t'occupant de la sono et du vidéoprojecteur d'une fête que tu donnes le meilleur de toi. Exemple : le jour de l'anniversaire, tu branches la sono, tu règles le son et tu fais marcher le vidéoprojecteur pour le diaporama de photos. | D6: Non | E6: =Questions!E6 -> T | F6: =IF(Questions!F6="Oui",B6,"")
A7: =Questions!A7 -> 6 | B7: =Questions!B7 -> 2 | C7: =Questions!D7&CHAR(10)&Questions!G7 -> C'est quand un prof te donne un modèle précis à suivre étape par étape que tu produis tes meilleurs résultats. Exemple : le prof donne une fiche : un titre, trois parties, une conclusion, avec la longueur de chacune. Tu suis les étapes une par une. | D7: Non | E7: =Questions!E7 -> F | F7: =IF(Questions!F7="Oui",B7,"") | H7: Résultat
A8: =Questions!A8 -> 7 | B8: =Questions!B8 -> 3 | C8: =Questions!D8&CHAR(10)&Questions!G8 -> C'est quand tu prépares le matériel pendant qu'un autre présente que tu donnes le meilleur de toi. Exemple : pendant qu'un camarade présente, toi tu as préparé les diapositives, les documents et le matériel, et tu les passes au bon moment. | D8: Non | E8: =Questions!E8 -> C | F8: =IF(Questions!F8="Oui",B8,"") | H8: Code du profil | J8: =IF(SUMPRODUCT(--(N2:N5="?"))>0,"",N2&N3&N4&N5) -> HIVE
A9: =Questions!A9 -> 8 | B9: =Questions!B9 -> 4 | C9: =Questions!D9&CHAR(10)&Questions!G9 -> C'est en discutant avec d'autres que tu apprends le mieux. Exemple : tu révises un chapitre de maths. Tu en parles avec un ami et vous vous expliquez les points difficiles. | D9: Non | E9: =Questions!E9 -> K | F9: =IF(Questions!F9="Oui",B9,"") | H9: Métier suggéré | J9: =IFERROR(INDEX(Metiers!$B$2:$B$17,MATCH($J$8,Metiers!$A$2:$A$17,0)),"Réponds aux 32 questions") -> UX / UI designer
A10: =Questions!A10 -> 9 | B10: =Questions!B10 -> 1 | C10: =Questions!D10&CHAR(10)&Questions!G10 -> C'est quand tu te demandes à qui sert un objet et si les gens l'aimeront que tu as tes meilleures idées. Exemple : on te montre une montre connectée. Ta première réaction : « Qui s'en servirait ? Mes grands-parents ? Mes amis sportifs ? Est-ce qu'ils aimeraient ça ? » | D10: Oui | E10: =Questions!E10 -> H | F10: =IF(Questions!F10="Oui",B10,"") | H10: Ce que fait le professionnel | J10: =IFERROR(INDEX(Metiers!$D$2:$D$17,MATCH($J$8,Metiers!$A$2:$A$17,0)),"") -> Imagine le visuel, les couleurs et la facilité d'utilisation des sites web et des applications mobiles.
A11: =Questions!A11 -> 10 | B11: =Questions!B11 -> 2 | C11: =Questions!D11&CHAR(10)&Questions!G11 -> C'est à la dernière minute que tu produis les meilleurs résultats. Exemple : un devoir est à rendre demain matin. Tu t'y mets la veille au soir, et c'est là que tes meilleures idées arrivent. | D11: Oui | E11: =Questions!E11 -> I | F11: =IF(Questions!F11="Oui",B11,"") | H11: Étape de l'anniversaire | J11: =IFERROR(INDEX(Metiers!$E$2:$E$17,MATCH($J$8,Metiers!$A$2:$A$17,0)),"") -> Conception : dessine l'écran d'invitation
A12: =Questions!A12 -> 11 | B12: =Questions!B12 -> 3 | C12: =Questions!D12&CHAR(10)&Questions!G12 -> C'est en disant clairement ce que tu penses, même si ça crée de la tension, que tu défends le mieux tes idées. Exemple : en débat, un camarade n'est pas d'accord avec toi. Tu expliques clairement pourquoi tu penses autrement, même si la discussion devient tendue. | D12: Oui | E12: =Questions!E12 -> V | F12: =IF(Questions!F12="Oui",B12,"") | H12: Compétences durables | J12: =IFERROR(INDEX(Metiers!$F$2:$F$17,MATCH($J$8,Metiers!$A$2:$A$17,0)),"") -> Créer et innover ; Communiquer et expliquer ; Apprendre à apprendre
A13: =Questions!A13 -> 12 | B13: =Questions!B13 -> 4 | C13: =Questions!D13&CHAR(10)&Questions!G13 -> C'est quand tu te plonges à fond dans un sujet qui te passionne que tu deviens le plus fort(e). Exemple : tu découvres un sujet qui te passionne (dinosaures, code, musique) et tu y passes tes week-ends jusqu'à tout savoir dessus. | D13: Oui | E13: =Questions!E13 -> E | F13: =IF(Questions!F13="Oui",B13,"") | H13: Matières à valoriser | J13: =IFERROR(INDEX(Metiers!$G$2:$G$17,MATCH($J$8,Metiers!$A$2:$A$17,0)),"") -> Arts plastiques ; Français ; Technologie ; Histoire-géographie
A14: =Questions!A14 -> 13 | B14: =Questions!B14 -> 1 | C14: =Questions!D14&CHAR(10)&Questions!G14 -> C'est quand ton téléphone bugue et que tu fouilles dans les réglages que tu es le plus efficace. Exemple : ton téléphone se fige en plein jeu. Tu ouvres les réglages, tu testes plusieurs options et tu continues jusqu'à ce qu'il remarche. | D14: Non | E14: =Questions!E14 -> T | F14: =IF(Questions!F14="Oui",B14,"") | H14: Voies de formation (pistes) | J14: =IFERROR(INDEX(Metiers!$H$2:$H$17,MATCH($J$8,Metiers!$A$2:$A$17,0)),"") -> BUT Métiers du multimédia et de l'internet ; DN MADE numérique ; écoles de design
A15: =Questions!A15 -> 14 | B15: =Questions!B15 -> 2 | C15: =Questions!D15&CHAR(10)&Questions!G15 -> C'est quand tu as pu tout préparer à l'avance que tu produis les meilleurs résultats. Exemple : un devoir est à rendre dans une semaine. Tu le prépares par étapes dès les premiers jours et tu rends un travail dont tu es content(e). | D15: Non | E15: =Questions!E15 -> F | F15: =IF(Questions!F15="Oui",B15,"") | H15: Métier voisin à explorer | J15: =IFERROR(INDEX(Metiers!$I$2:$I$17,MATCH($J$8,Metiers!$A$2:$A$17,0)),"") -> Community manager
A16: =Questions!A16 -> 15 | B16: =Questions!B16 -> 3 | C16: =Questions!D16&CHAR(10)&Questions!G16 -> C'est quand tu laisses passer un désaccord en classe pour garder le calme que tu te sens le mieux. Exemple : en classe, quelqu'un te contredit. Tu choisis de ne pas insister pour que la discussion reste calme. | D16: Non | E16: =Questions!E16 -> C | F16: =IF(Questions!F16="Oui",B16,"") | H16: Fiabilité des réponses | J16: =IF(COUNTA($D$2:$D$33)<32,"",IF(OR(COUNTIF($D$2:$D$33,"Oui")>=26,COUNTIF($D$2:$D$33,"Oui")<=6),"Attention : presque que des Oui (ou que des Non), résultat peu fiable","Réponses variées : résultat exploitable")) -> Réponses variées : résultat exploitable
A17: =Questions!A17 -> 16 | B17: =Questions!B17 -> 4 | C17: =Questions!D17&CHAR(10)&Questions!G17 -> C'est en répartissant les rôles et en coordonnant tout le monde que tu fais le mieux avancer un projet de groupe. Exemple : dans un projet de groupe, tu dis « Toi tu cherches, toi tu rédiges, toi tu fais l'affiche » et tu suis l'avancement de chacun. | D17: Non | E17: =Questions!E17 -> K | F17: =IF(Questions!F17="Oui",B17,"")
A18: =Questions!A18 -> 17 | B18: =Questions!B18 -> 1 | C18: =Questions!D18&CHAR(10)&Questions!G18 -> C'est quand tu dois captiver ceux qui t'écoutent (exposé, présentation) que tu produis tes meilleurs résultats. Exemple : tu dois présenter un exposé à la classe. Tu cherches une accroche, une anecdote ou une question pour que tout le monde écoute jusqu'au bout. | D18: Oui | E18: =Questions!E18 -> H | F18: =IF(Questions!F18="Oui",B18,"") | H18: Légende : cellules jaunes = réponses à saisir (Oui ou Non). Les réponses d'exemple (profil HIVE) sont à remplacer.
A19: =Questions!A19 -> 18 | B19: =Questions!B19 -> 2 | C19: =Questions!D19&CHAR(10)&Questions!G19 -> C'est en inventant une nouvelle règle ou une nouvelle version d'un jeu de société que tu t'amuses le plus. Exemple : en jouant au Uno ou au Monopoly, tu proposes une règle de ton invention (un défi, un bonus) pour pimenter la partie. | D19: Oui | E19: =Questions!E19 -> I | F19: =IF(Questions!F19="Oui",B19,"") | H19: Un Oui ajoute 1 point au pôle visé ; égalité : la question décisive de l'axe tranche.
A20: =Questions!A20 -> 19 | B20: =Questions!B20 -> 3 | C20: =Questions!D20&CHAR(10)&Questions!G20 -> C'est quand on voit ce que tu as créé (dessin, projet, vidéo) que tu te sens le plus motivé(e). Exemple : tu fais un dessin, une vidéo ou un projet de techno ; il est affiché ou partagé et les autres peuvent le voir et réagir. | D20: Oui | E20: =Questions!E20 -> V | F20: =IF(Questions!F20="Oui",B20,"")
A21: =Questions!A21 -> 20 | B21: =Questions!B21 -> 4 | C21: =Questions!D21&CHAR(10)&Questions!G21 -> C'est en prenant en charge seul(e) une partie difficile d'un projet de groupe que tu donnes le meilleur de toi. Exemple : dans le projet de groupe, la partie la plus compliquée (le code, le calcul) ne tente personne ; tu la prends et tu la finis seul(e). | D21: Oui | E21: =Questions!E21 -> E | F21: =IF(Questions!F21="Oui",B21,"") | H21: Famille de métiers (France Travail) | J21: =IFERROR(INDEX(Metiers!$L$2:$L$17,MATCH($J$8,Metiers!$A$2:$A$17,0)),"") -> 3 – Design, développement, test et ops
A22: =Questions!A22 -> 21 | B22: =Questions!B22 -> 1 | C22: =Questions!D22&CHAR(10)&Questions!G22 -> C'est en testant tous les boutons d'un nouvel appareil que tu comprends le mieux comment il marche. Exemple : tu reçois une enceinte ou une manette que tu ne connais pas. Tu appuies sur chaque bouton pour voir ce qui se passe, avant même d'ouvrir la notice. | D22: Non | E22: =Questions!E22 -> T | F22: =IF(Questions!F22="Oui",B22,"") | H22: Famille voisine à explorer | J22: =IFERROR(INDEX(Metiers!$M$2:$M$17,MATCH($J$8,Metiers!$A$2:$A$17,0)),"") -> 5 – Marketing digital, communication et e-commerce
A23: =Questions!A23 -> 22 | B23: =Questions!B23 -> 2 | C23: =Questions!D23&CHAR(10)&Questions!G23 -> C'est en connaissant toutes les règles d'un jeu de société et en vérifiant qu'elles sont respectées que tu t'amuses le plus. Exemple : pendant une partie, tu connais la règle exacte et tu rappelles à tes amis qui doit jouer et comment se calculent les points. | D23: Non | E23: =Questions!E23 -> F | F23: =IF(Questions!F23="Oui",B23,"")
A24: =Questions!A24 -> 23 | B24: =Questions!B24 -> 3 | C24: =Questions!D24&CHAR(10)&Questions!G24 -> C'est quand tu travailles dans ton coin, sans que ton travail soit forcément montré, que tu produis tes meilleurs résultats. Exemple : tu passes un après-midi à avancer sur ton projet dans ton coin, sans le montrer avant qu'il soit fini. | D24: Non | E24: =Questions!E24 -> C | F24: =IF(Questions!F24="Oui",B24,"")
A25: =Questions!A25 -> 24 | B25: =Questions!B25 -> 4 | C25: =Questions!D25&CHAR(10)&Questions!G25 -> C'est en lançant un projet avec plusieurs amis que tu es le plus motivé(e). Exemple : tu proposes à tes amis de monter ensemble une chaîne vidéo, un club ou un tournoi. | D25: Non | E25: =Questions!E25 -> K | F25: =IF(Questions!F25="Oui",B25,"")
A26: =Questions!A26 -> 25 | B26: =Questions!B26 -> 1 | C26: =Questions!D26&CHAR(10)&Questions!G26 -> C'est en observant les gens que tu devines le mieux ce qui leur ferait plaisir. Exemple : à la cantine ou au repas de famille, tu remarques ce qu'un ami regarde ou aime, et tu en déduis le cadeau qui lui plairait. | D26: Oui | E26: =Questions!E26 -> H | F26: =IF(Questions!F26="Oui",B26,"")
A27: =Questions!A27 -> 26 | B27: =Questions!B27 -> 2 | C27: =Questions!D27&CHAR(10)&Questions!G27 -> C'est quand il manque un matériel et que tu bricoles une solution avec ce que tu as sous la main que tu es le plus à ton aise. Exemple : pour un projet de techno, tu n'as pas de colle : tu fabriques une fixation avec du scotch, des élastiques ou du carton. | D27: Oui | E27: =Questions!E27 -> I | F27: =IF(Questions!F27="Oui",B27,"")
A28: =Questions!A28 -> 27 | B28: =Questions!B28 -> 3 | C28: =Questions!D28&CHAR(10)&Questions!G28 -> C'est en préparant tout en coulisses d'une fête (musique, lumières) que tu t'éclates le plus. Exemple : pendant une fête, tu gères la playlist et les lumières depuis un coin de la pièce pendant que les autres dansent. | D28: Non | E28: =Questions!E28 -> C | F28: =IF(Questions!F28="Oui",B28,"")
A29: =Questions!A29 -> 28 | B29: =Questions!B29 -> 4 | C29: =Questions!D29&CHAR(10)&Questions!G29 -> C'est en étant capitaine d'une équipe que tu donnes le meilleur de toi. Exemple : dans un match, le capitaine choisit les postes, encourage l'équipe et parle à l'arbitre : c'est le rôle que tu prends. | D29: Non | E29: =Questions!E29 -> K | F29: =IF(Questions!F29="Oui",B29,"")
A30: =Questions!A30 -> 29 | B30: =Questions!B30 -> 1 | C30: =Questions!D30&CHAR(10)&Questions!G30 -> C'est quand tu comprends comment un jeu vidéo est fabriqué qu'il t'intéresse le plus. Exemple : en jouant, tu te demandes comment les développeurs ont programmé les mouvements du personnage ou la physique du jeu. | D30: Non | E30: =Questions!E30 -> T | F30: =IF(Questions!F30="Oui",B30,"") -> 1
A31: =Questions!A31 -> 30 | B31: =Questions!B31 -> 2 | C31: =Questions!D31&CHAR(10)&Questions!G31 -> C'est quand tu cherches méthodiquement ce qui cause un problème que tu es le plus efficace. Exemple : une lampe ne s'allume plus. Tu vérifies l'ampoule, la prise, l'interrupteur, un par un, pour trouver où ça bloque. | D31: Non | E31: =Questions!E31 -> F | F31: =IF(Questions!F31="Oui",B31,"") -> 2
A32: =Questions!A32 -> 31 | B32: =Questions!B32 -> 3 | C32: =Questions!D32&CHAR(10)&Questions!G32 -> C'est en accueillant les invités et en lançant l'ambiance d'une fête que tu t'éclates le plus. Exemple : à l'entrée de la fête, tu accueilles chaque invité avec le sourire et tu lances le premier jeu ou la première danse. | D32: Oui | E32: =Questions!E32 -> V | F32: =IF(Questions!F32="Oui",B32,"") -> 3
A33: =Questions!A33 -> 32 | B33: =Questions!B33 -> 4 | C33: =Questions!D33&CHAR(10)&Questions!G33 -> C'est en devenant le ou la spécialiste de quelque chose que tu te sens le plus accompli(e). Exemple : tu t'imagines dans dix ans : on vient te voir parce que tu es la personne qui connaît tout sur ton sujet. | D33: Oui | E33: =Questions!E33 -> E | F33: =IF(Questions!F33="Oui",B33,"") -> 4

Sheet Axes
A1: Axe | B1: Nom de l'axe | C1: Question posée | D1: Pôle 1 (code) | E1: Pôle 1 | F1: Pôle 2 (code) | G1: Pôle 2 | H1: Ce que mesure l'axe | I1: Compétences durables liées (pôle 1 / pôle 2)
A2: 1 | B2: Ce qui m'attire | C2: Qu'est-ce qui m'intéresse le plus dans un projet ? | D2: H | E2: Les personnes (utilisateurs, équipes) | F2: T | G2: La technique (code, données, machines) | H2: Tourné vers les gens ou vers les systèmes | I2: Coopérer en équipe, Communiquer et expliquer / Résoudre avec méthode, Analyser et raisonner
A3: 2 | B3: Ma démarche | C3: Comment j'aime agir ? | D3: I | E3: Improviser et inventer (créer sur le moment, faire autrement) | F3: F | G3: Préparer et fiabiliser (anticiper, vérifier) | H3: Goût de la création ou de l'analyse et de la fiabilité | I3: Créer et innover / Analyser et raisonner, Résoudre avec méthode
A4: 3 | B4: Mon terrain | C4: Où je me sens à ma place ? | D4: V | E4: Côté visible (se montrer, être au contact) | F4: C | G4: Coulisses (rester en retrait, préparer) | H4: Contact avec les utilisateurs ou travail en arrière-plan | I4: Communiquer et expliquer / Apprendre à apprendre, Résoudre avec méthode
A5: 4 | B5: Ma façon de travailler | C5: Comment je préfère travailler ? | D5: E | E5: Expertise en profondeur (je maîtrise à fond) | F5: K | G5: Collectif et coordination (je fais avancer ensemble) | H5: Expertise individuelle ou travail collectif | I5: Apprendre à apprendre, Se connaître et s'engager / Coopérer en équipe, S'adapter et rebondir

Sheet Questions
A1: N° de passation | B1: Axe | C1: Nom de l'axe | D1: Affirmation (Oui = c'est vrai pour moi, Non = pas vraiment) | E1: Pôle visé | F1: Décisive | G1: Mise en situation illustrative
A2: 1 | B2: 1 | C2: Ce qui m'attire | D2: C'est en accueillant les invités d'une fête, en veillant à ce que chacun se sente bien, que tu donnes le meilleur de toi. | E2: H | G2: Exemple : pour l'anniversaire de ton meilleur ami, tu es à la porte, tu salues chaque invité, tu présentes ceux qui ne se connaissent pas et tu veilles à ce que personne ne reste seul dans son coin.
A3: 2 | B3: 2 | C3: Ma démarche | D3: C'est quand un prof te laisse choisir librement comment présenter ton travail que tu produis tes meilleurs résultats. | E3: I | G3: Exemple : le prof dit « Présentez ce thème comme vous voulez : affiche, vidéo, saynète… ». Tu choisis ton format et tu te lances.
A4: 3 | B4: 3 | C4: Mon terrain | D4: C'est quand tu présentes ton travail devant la classe que tu donnes le meilleur de toi. | E4: V | G4: Exemple : ton groupe a fini son exposé et tu te lèves devant la classe pour le présenter.
A5: 4 | B5: 4 | C5: Ma façon de travailler | D5: C'est quand tu apprends seul(e) que tu retiens le mieux. | E5: E | G5: Exemple : tu veux apprendre une nouvelle technique de dessin ou un nouveau tour de magie. Tu regardes un tutoriel et tu t'entraînes seul(e) jusqu'à y arriver.
A6: 5 | B6: 1 | C6: Ce qui m'attire | D6: C'est en t'occupant de la sono et du vidéoprojecteur d'une fête que tu donnes le meilleur de toi. | E6: T | G6: Exemple : le jour de l'anniversaire, tu branches la sono, tu règles le son et tu fais marcher le vidéoprojecteur pour le diaporama de photos.
A7: 6 | B7: 2 | C7: Ma démarche | D7: C'est quand un prof te donne un modèle précis à suivre étape par étape que tu produis tes meilleurs résultats. | E7: F | G7: Exemple : le prof donne une fiche : un titre, trois parties, une conclusion, avec la longueur de chacune. Tu suis les étapes une par une.
A8: 7 | B8: 3 | C8: Mon terrain | D8: C'est quand tu prépares le matériel pendant qu'un autre présente que tu donnes le meilleur de toi. | E8: C | G8: Exemple : pendant qu'un camarade présente, toi tu as préparé les diapositives, les documents et le matériel, et tu les passes au bon moment.
A9: 8 | B9: 4 | C9: Ma façon de travailler | D9: C'est en discutant avec d'autres que tu apprends le mieux. | E9: K | G9: Exemple : tu révises un chapitre de maths. Tu en parles avec un ami et vous vous expliquez les points difficiles.
A10: 9 | B10: 1 | C10: Ce qui m'attire | D10: C'est quand tu te demandes à qui sert un objet et si les gens l'aimeront que tu as tes meilleures idées. | E10: H | G10: Exemple : on te montre une montre connectée. Ta première réaction : « Qui s'en servirait ? Mes grands-parents ? Mes amis sportifs ? Est-ce qu'ils aimeraient ça ? »
A11: 10 | B11: 2 | C11: Ma démarche | D11: C'est à la dernière minute que tu produis les meilleurs résultats. | E11: I | G11: Exemple : un devoir est à rendre demain matin. Tu t'y mets la veille au soir, et c'est là que tes meilleures idées arrivent.
A12: 11 | B12: 3 | C12: Mon terrain | D12: C'est en disant clairement ce que tu penses, même si ça crée de la tension, que tu défends le mieux tes idées. | E12: V | G12: Exemple : en débat, un camarade n'est pas d'accord avec toi. Tu expliques clairement pourquoi tu penses autrement, même si la discussion devient tendue.
A13: 12 | B13: 4 | C13: Ma façon de travailler | D13: C'est quand tu te plonges à fond dans un sujet qui te passionne que tu deviens le plus fort(e). | E13: E | G13: Exemple : tu découvres un sujet qui te passionne (dinosaures, code, musique) et tu y passes tes week-ends jusqu'à tout savoir dessus.
... A29: 28 | B29: 4 | C29: Ma façon de travailler | D29: C'est en étant capitaine d'une équipe que tu donnes le meilleur de toi. | E29: K | G29: Exemple : dans un match, le capitaine choisit les postes, encourage l'équipe et parle à l'arbitre : c'est le rôle que tu prends.
A30: 29 | B30: 1 | C30: Ce qui m'attire | D30: C'est quand tu comprends comment un jeu vidéo est fabriqué qu'il t'intéresse le plus. | E30: T | F30: Oui | G30: Exemple : en jouant, tu te demandes comment les développeurs ont programmé les mouvements du personnage ou la physique du jeu.
A31: 30 | B31: 2 | C31: Ma démarche | D31: C'est quand tu cherches méthodiquement ce qui cause un problème que tu es le plus efficace. | E31: F | F31: Oui | G31: Exemple : une lampe ne s'allume plus. Tu vérifies l'ampoule, la prise, l'interrupteur, un par un, pour trouver où ça bloque.
A32: 31 | B32: 3 | C32: Mon terrain | D32: C'est en accueillant les invités et en lançant l'ambiance d'une fête que tu t'éclates le plus. | E32: V | F32: Oui | G32: Exemple : à l'entrée de la fête, tu accueilles chaque invité avec le sourire et tu lances le premier jeu ou la première danse.
A33: 32 | B33: 4 | C33: Ma façon de travailler | D33: C'est en devenant le ou la spécialiste de quelque chose que tu te sens le plus accompli(e). | E33: E | F33: Oui | G33: Exemple : tu t'imagines dans dix ans : on vient te voir parce que tu es la personne qui connaît tout sur ton sujet.

Sheet Matrice
A1: N° de passation | B1: Axe | C1: Nom de l'axe | D1: Question posée (Oui / Non) | E1: Pôle 1 (code) | F1: Pôle 1 | G1: Pôle 2 (code) | H1: Pôle 2 | I1: Ce que mesure l'axe | J1: Compétences durables liées | K1: Question équivalente vie quotidienne collégien | L1: Mise en situation quotidienne | M1: Pôle visé si Oui | N1: Pôle visé si Non | O1: Décisive (axe) | P1: Famille(s) de métiers de la tech associée(s) au pôle visé | Q1: Idées de métiers associés au pôle visé | R1: Matières au collège / lycée à valoriser | S1: Source
A2: =Questions!A2 -> 1 | B2: =Questions!B2 -> 1 | C2: =Questions!C2 -> Ce qui m'attire | D2: =Questions!D2 -> C'est en accueillant les invités d'une fête, en veillant à ce que chacun se sente bien, que tu donnes le meilleur de toi. | E2: =INDEX(Axes!$D$2:$D$5,MATCH($B2,Axes!$A$2:$A$5,0)) -> H | F2: =INDEX(Axes!$E$2:$E$5,MATCH($B2,Axes!$A$2:$A$5,0)) -> Les personnes (utilisateurs, équipes) | G2: =INDEX(Axes!$F$2:$F$5,MATCH($B2,Axes!$A$2:$A$5,0)) -> T | H2: =INDEX(Axes!$G$2:$G$5,MATCH($B2,Axes!$A$2:$A$5,0)) -> La technique (code, données, machines) | I2: =INDEX(Axes!$H$2:$H$5,MATCH($B2,Axes!$A$2:$A$5,0)) -> Tourné vers les gens ou vers les systèmes | J2: =INDEX(Axes!$I$2:$I$5,MATCH($B2,Axes!$A$2:$A$5,0)) -> Coopérer en équipe, Communiquer et expliquer / Résoudre avec méthode, Analyser et raisonner | K2: Tu es à l'aise pour mettre les autres à l'aise ? | L2: =SUBSTITUTE(Questions!G2,"Exemple : ","") -> pour l'anniversaire de ton meilleur ami, tu es à la porte, tu salues chaque invité, tu présentes ceux qui ne se connaissent pas et tu veilles à ce que personne ne reste seul dans son coin. | M2: =Questions!E2 -> H | N2: =IF(M2=E2,G2,E2) -> T | O2: =IF(Questions!F2="Oui","Oui","") | P2: 5 Marketing digital, communication et e-commerce ; 7 Stratégie et gestion de projet ; 3 Design (UX) | Q2: UX / UI designer ; Community manager ; Chef·fe de projet digital ; Technico-commercial·e tech | R2: Français ; Anglais ; Arts plastiques ; Histoire-géographie | S2: Questions : version validée par Joelle (« C'est… que tu… »). Familles : « Le Numérique en 7 familles », France Travail. Rattachements pôle → famille indicatifs, à valider.
A3: =Questions!A3 -> 2 | B3: =Questions!B3 -> 2 | C3: =Questions!C3 -> Ma démarche | D3: =Questions!D3 -> C'est quand un prof te laisse choisir librement comment présenter ton travail que tu produis tes meilleurs résultats. | E3: =INDEX(Axes!$D$2:$D$5,MATCH($B3,Axes!$A$2:$A$5,0)) -> I | F3: =INDEX(Axes!$E$2:$E$5,MATCH($B3,Axes!$A$2:$A$5,0)) -> Improviser et inventer (créer sur le moment, faire autrement) | G3: =INDEX(Axes!$F$2:$F$5,MATCH($B3,Axes!$A$2:$A$5,0)) -> F | H3: =INDEX(Axes!$G$2:$G$5,MATCH($B3,Axes!$A$2:$A$5,0)) -> Préparer et fiabiliser (anticiper, vérifier) | I3: =INDEX(Axes!$H$2:$H$5,MATCH($B3,Axes!$A$2:$A$5,0)) -> Goût de la création ou de l'analyse et de la fiabilité | J3: =INDEX(Axes!$I$2:$I$5,MATCH($B3,Axes!$A$2:$A$5,0)) -> Créer et innover / Analyser et raisonner, Résoudre avec méthode | K3: Tu es plus créatif(ve) quand on te laisse choisir ta façon de faire ? | L3: =SUBSTITUTE(Questions!G3,"Exemple : ","") -> le prof dit « Présentez ce thème comme vous voulez : affiche, vidéo, saynète… ». Tu choisis ton format et tu te lances. | M3: =Questions!E3 -> I | N3: =IF(M3=E3,G3,E3) -> F | O3: =IF(Questions!F3="Oui","Oui","") | P3: 3 Design, développement, test et ops ; 2 Robotique et IoT ; 4 Data et IA ; 5 Marketing digital | Q3: Développeur·se d'applications ; UX / UI designer ; Expert·e en IA ; Community manager | R3: Arts plastiques ; Technologie ; Mathématiques ; Français | S3: Questions : version validée par Joelle (« C'est… que tu… »). Familles : « Le Numérique en 7 familles », France Travail. Rattachements pôle → famille indicatifs, à valider.
A4: =Questions!A4 -> 3 | B4: =Questions!B4 -> 3 | C4: =Questions!C4 -> Mon terrain | D4: =Questions!D4 -> C'est quand tu présentes ton travail devant la classe que tu donnes le meilleur de toi. | E4: =INDEX(Axes!$D$2:$D$5,MATCH($B4,Axes!$A$2:$A$5,0)) -> V | F4: =INDEX(Axes!$E$2:$E$5,MATCH($B4,Axes!$A$2:$A$5,0)) -> Côté visible (se montrer, être au contact) | G4: =INDEX(Axes!$F$2:$F$5,MATCH($B4,Axes!$A$2:$A$5,0)) -> C | H4: =INDEX(Axes!$G$2:$G$5,MATCH($B4,Axes!$A$2:$A$5,0)) -> Coulisses (rester en retrait, préparer) | I4: =INDEX(Axes!$H$2:$H$5,MATCH($B4,Axes!$A$2:$A$5,0)) -> Contact avec les utilisateurs ou travail en arrière-plan | J4: =INDEX(Axes!$I$2:$I$5,MATCH($B4,Axes!$A$2:$A$5,0)) -> Communiquer et expliquer / Apprendre à apprendre, Résoudre avec méthode | K4: Tu aimes présenter ton travail devant la classe ? | L4: =SUBSTITUTE(Questions!G4,"Exemple : ","") -> ton groupe a fini son exposé et tu te lèves devant la classe pour le présenter. | M4: =Questions!E4 -> V | N4: =IF(M4=E4,G4,E4) -> C | O4: =IF(Questions!F4="Oui","Oui","") | P4: 5 Marketing digital, communication et e-commerce ; 7 Stratégie et gestion de projet ; 3 Design (UX) | Q4: Community manager ; Technico-commercial·e tech ; Chef·fe de projet digital ; UX / UI designer | R4: Français ; Anglais ; Arts plastiques ; Enseignement moral et civique | S4: Questions : version validée par Joelle (« C'est… que tu… »). Familles : « Le Numérique en 7 familles », France Travail. Rattachements pôle → famille indicatifs, à valider.
A5: =Questions!A5 -> 4 | B5: =Questions!B5 -> 4 | C5: =Questions!C5 -> Ma façon de travailler | D5: =Questions!D5 -> C'est quand tu apprends seul(e) que tu retiens le mieux. | E5: =INDEX(Axes!$D$2:$D$5,MATCH($B5,Axes!$A$2:$A$5,0)) -> E | F5: =INDEX(Axes!$E$2:$E$5,MATCH($B5,Axes!$A$2:$A$5,0)) -> Expertise en profondeur (je maîtrise à fond) | G5: =INDEX(Axes!$F$2:$F$5,MATCH($B5,Axes!$A$2:$A$5,0)) -> K | H5: =INDEX(Axes!$G$2:$G$5,MATCH($B5,Axes!$A$2:$A$5,0)) -> Collectif et coordination (je fais avancer ensemble) | I5: =INDEX(Axes!$H$2:$H$5,MATCH($B5,Axes!$A$2:$A$5,0)) -> Expertise individuelle ou travail collectif | J5: =INDEX(Axes!$I$2:$I$5,MATCH($B5,Axes!$A$2:$A$5,0)) -> Apprendre à apprendre, Se connaître et s'engager / Coopérer en équipe, S'adapter et rebondir | K5: Tu retiens mieux quand tu apprends seul(e) ? | L5: =SUBSTITUTE(Questions!G5,"Exemple : ","") -> tu veux apprendre une nouvelle technique de dessin ou un nouveau tour de magie. Tu regardes un tutoriel et tu t'entraînes seul(e) jusqu'à y arriver. | M5: =Questions!E5 -> E | N5: =IF(M5=E5,G5,E5) -> K | O5: =IF(Questions!F5="Oui","Oui","") | P5: 4 Data et IA ; 6 Cybersécurité ; 2 Robotique et IoT ; 3 Développement | Q5: Expert·e en IA ; Data scientist ; Pentesteur·se ; Spécialiste robotique | R5: Mathématiques ; Physique-chimie ; Technologie ; Anglais | S5: Questions : version validée par Joelle (« C'est… que tu… »). Familles : « Le Numérique en 7 familles », France Travail. Rattachements pôle → famille indicatifs, à valider.
A6: =Questions!A6 -> 5 | B6: =Questions!B6 -> 1 | C6: =Questions!C6 -> Ce qui m'attire | D6: =Questions!D6 -> C'est en t'occupant de la sono et du vidéoprojecteur d'une fête que tu donnes le meilleur de toi. | E6: =INDEX(Axes!$D$2:$D$5,MATCH($B6,Axes!$A$2:$A$5,0)) -> H | F6: =INDEX(Axes!$E$2:$E$5,MATCH($B6,Axes!$A$2:$A$5,0)) -> Les personnes (utilisateurs, équipes) | G6: =INDEX(Axes!$F$2:$F$5,MATCH($B6,Axes!$A$2:$A$5,0)) -> T | H6: =INDEX(Axes!$G$2:$G$5,MATCH($B6,Axes!$A$2:$A$5,0)) -> La technique (code, données, machines) | I6: =INDEX(Axes!$H$2:$H$5,MATCH($B6,Axes!$A$2:$A$5,0)) -> Tourné vers les gens ou vers les systèmes | J6: =INDEX(Axes!$I$2:$I$5,MATCH($B6,Axes!$A$2:$A$5,0)) -> Coopérer en équipe, Communiquer et expliquer / Résoudre avec méthode, Analyser et raisonner | K6: Tu aimes t'occuper du matériel son et vidéo ? | L6: =SUBSTITUTE(Questions!G6,"Exemple : ","") -> le jour de l'anniversaire, tu branches la sono, tu règles le son et tu fais marcher le vidéoprojecteur pour le diaporama de photos. | M6: =Questions!E6 -> T | N6: =IF(M6=E6,G6,E6) -> H | O6: =IF(Questions!F6="Oui","Oui","") | P6: 1 Infrastructures, cloud et réseaux ; 2 Robotique et IoT ; 4 Data et IA ; 6 Cybersécurité | Q6: Développeur·se d'applications ; Spécialiste robotique ; Pentesteur·se ; Spécialiste systèmes, réseaux et cloud | R6: Mathématiques ; Technologie ; Physique-chimie ; Anglais | S6: Questions : version validée par Joelle (« C'est… que tu… »). Familles : « Le Numérique en 7 familles », France Travail. Rattachements pôle → famille indicatifs, à valider.
A7: =Questions!A7 -> 6 | B7: =Questions!B7 -> 2 | C7: =Questions!C7 -> Ma démarche | D7: =Questions!D7 -> C'est quand un prof te donne un modèle précis à suivre étape par étape que tu produis tes meilleurs résultats. | E7: =INDEX(Axes!$D$2:$D$5,MATCH($B7,Axes!$A$2:$A$5,0)) -> I | F7: =INDEX(Axes!$E$2:$E$5,MATCH($B7,Axes!$A$2:$A$5,0)) -> Improviser et inventer (créer sur le moment, faire autrement) | G7: =INDEX(Axes!$F$2:$F$5,MATCH($B7,Axes!$A$2:$A$5,0)) -> F | H7: =INDEX(Axes!$G$2:$G$5,MATCH($B7,Axes!$A$2:$A$5,0)) -> Préparer et fiabiliser (anticiper, vérifier) | I7: =INDEX(Axes!$H$2:$H$5,MATCH($B7,Axes!$A$2:$A$5,0)) -> Goût de la création ou de l'analyse et de la fiabilité | J7: =INDEX(Axes!$I$2:$I$5,MATCH($B7,Axes!$A$2:$A$5,0)) -> Créer et innover / Analyser et raisonner, Résoudre avec méthode | K7: Tu travailles mieux avec un modèle précis à suivre ? | L7: =SUBSTITUTE(Questions!G7,"Exemple : ","") -> le prof donne une fiche : un titre, trois parties, une conclusion, avec la longueur de chacune. Tu suis les étapes une par une. | M7: =Questions!E7 -> F | N7: =IF(M7=E7,G7,E7) -> I | O7: =IF(Questions!F7="Oui","Oui","") | P7: 6 Cybersécurité ; 3 Test et qualité ; 1 Maintien en condition opérationnelle ; 4 Data et IA | Q7: Testeur·se et ingénieur·e qualité ; Pentesteur·se ; Data scientist ; Délégué·e à la protection des données | R7: Mathématiques ; Technologie ; Français ; Anglais | S7: Questions : version validée par Joelle (« C'est… que tu… »). Familles : « Le Numérique en 7 familles », France Travail. Rattachements pôle → famille indicatifs, à valider.
A8: =Questions!A8 -> 7 | B8: =Questions!B8 -> 3 | C8: =Questions!C8 -> Mon terrain | D8: =Questions!D8 -> C'est quand tu prépares le matériel pendant qu'un autre présente que tu donnes le meilleur de toi. | E8: =INDEX(Axes!$D$2:$D$5,MATCH($B8,Axes!$A$2:$A$5,0)) -> V | F8: =INDEX(Axes!$E$2:$E$5,MATCH($B8,Axes!$A$2:$A$5,0)) -> Côté visible (se montrer, être au contact) | G8: =INDEX(Axes!$F$2:$F$5,MATCH($B8,Axes!$A$2:$A$5,0)) -> C | H8: =INDEX(Axes!$G$2:$G$5,MATCH($B8,Axes!$A$2:$A$5,0)) -> Coulisses (rester en retrait, préparer) | I8: =INDEX(Axes!$H$2:$H$5,MATCH($B8,Axes!$A$2:$A$5,0)) -> Contact avec les utilisateurs ou travail en arrière-plan | J8: =INDEX(Axes!$I$2:$I$5,MATCH($B8,Axes!$A$2:$A$5,0)) -> Communiquer et expliquer / Apprendre à apprendre, Résoudre avec méthode | K8: Tu préfères préparer le matériel pendant qu'un autre présente ? | L8: =SUBSTITUTE(Questions!G8,"Exemple : ","") -> pendant qu'un camarade présente, toi tu as préparé les diapositives, les documents et le matériel, et tu les passes au bon moment. | M8: =Questions!E8 -> C | N8: =IF(M8=E8,G8,E8) -> V | O8: =IF(Questions!F8="Oui","Oui","") | P8: 1 Infrastructures, cloud et réseaux ; 6 Cybersécurité ; 4 Data et IA ; 3 Développement | Q8: Développeur·se back-end ; Spécialiste systèmes, réseaux et cloud ; Pentesteur·se ; Data scientist | R8: Mathématiques ; Technologie ; Physique-chimie ; Anglais | S8: Questions : version validée par Joelle (« C'est… que tu… »). Familles : « Le Numérique en 7 familles », France Travail. Rattachements pôle → famille indicatifs, à valider.
A9: =Questions!A9 -> 8 | B9: =Questions!B9 -> 4 | C9: =Questions!C9 -> Ma façon de travailler | D9: =Questions!D9 -> C'est en discutant avec d'autres que tu apprends le mieux. | E9: =INDEX(Axes!$D$2:$D$5,MATCH($B9,Axes!$A$2:$A$5,0)) -> E | F9: =INDEX(Axes!$E$2:$E$5,MATCH($B9,Axes!$A$2:$A$5,0)) -> Expertise en profondeur (je maîtrise à fond) | G9: =INDEX(Axes!$F$2:$F$5,MATCH($B9,Axes!$A$2:$A$5,0)) -> K | H9: =INDEX(Axes!$G$2:$G$5,MATCH($B9,Axes!$A$2:$A$5,0)) -> Collectif et coordination (je fais avancer ensemble) | I9: =INDEX(Axes!$H$2:$H$5,MATCH($B9,Axes!$A$2:$A$5,0)) -> Expertise individuelle ou travail collectif | J9: =INDEX(Axes!$I$2:$I$5,MATCH($B9,Axes!$A$2:$A$5,0)) -> Apprendre à apprendre, Se connaître et s'engager / Coopérer en équipe, S'adapter et rebondir | K9: Tu apprends mieux en discutant avec d'autres ? | L9: =SUBSTITUTE(Questions!G9,"Exemple : ","") -> tu révises un chapitre de maths. Tu en parles avec un ami et vous vous expliquez les points difficiles. | M9: =Questions!E9 -> K | N9: =IF(M9=E9,G9,E9) -> E | O9: =IF(Questions!F9="Oui","Oui","") | P9: 7 Stratégie et gestion de projet ; 1 Infrastructures (exploitation) ; 5 Marketing digital | Q9: Chef·fe de projet digital ; Technico-commercial·e tech ; Community manager ; Développeur·se back-end | R9: Français ; Anglais ; Mathématiques ; Histoire-géographie | S9: Questions : version validée par Joelle (« C'est… que tu… »). Familles : « Le Numérique en 7 familles », France Travail. Rattachements pôle → famille indicatifs, à valider.
A10: =Questions!A10 -> 9 | B10: =Questions!B10 -> 1 | C10: =Questions!C10 -> Ce qui m'attire | D10: =Questions!D10 -> C'est quand tu te demandes à qui sert un objet et si les gens l'aimeront que tu as tes meilleures idées. | E10: =INDEX(Axes!$D$2:$D$5,MATCH($B10,Axes!$A$2:$A$5,0)) -> H | F10: =INDEX(Axes!$E$2:$E$5,MATCH($B10,Axes!$A$2:$A$5,0)) -> Les personnes (utilisateurs, équipes) | G10: =INDEX(Axes!$F$2:$F$5,MATCH($B10,Axes!$A$2:$A$5,0)) -> T | H10: =INDEX(Axes!$G$2:$G$5,MATCH($B10,Axes!$A$2:$A$5,0)) -> La technique (code, données, machines) | I10: =INDEX(Axes!$H$2:$H$5,MATCH($B10,Axes!$A$2:$A$5,0)) -> Tourné vers les gens ou vers les systèmes | J10: =INDEX(Axes!$I$2:$I$5,MATCH($B10,Axes!$A$2:$A$5,0)) -> Coopérer en équipe, Communiquer et expliquer / Résoudre avec méthode, Analyser et raisonner | K10: Tu te demandes si les gens vont aimer un objet ? | L10: =SUBSTITUTE(Questions!G10,"Exemple : ","") -> on te montre une montre connectée. Ta première réaction : « Qui s'en servirait ? Mes grands-parents ? Mes amis sportifs ? Est-ce qu'ils aimeraient ça ? » | M10: =Questions!E10 -> H | N10: =IF(M10=E10,G10,E10) -> T | O10: =IF(Questions!F10="Oui","Oui","") | P10: 5 Marketing digital, communication et e-commerce ; 7 Stratégie et gestion de projet ; 3 Design (UX) | Q10: UX / UI designer ; Community manager ; Chef·fe de projet digital ; Technico-commercial·e tech | R10: Français ; Anglais ; Arts plastiques ; Histoire-géographie | S10: Questions : version validée par Joelle (« C'est… que tu… »). Familles : « Le Numérique en 7 familles », France Travail. Rattachements pôle → famille indicatifs, à valider.
A11: =Questions!A11 -> 10 | B11: =Questions!B11 -> 2 | C11: =Questions!C11 -> Ma démarche | D11: =Questions!D11 -> C'est à la dernière minute que tu produis les meilleurs résultats. | E11: =INDEX(Axes!$D$2:$D$5,MATCH($B11,Axes!$A$2:$A$5,0)) -> I | F11: =INDEX(Axes!$E$2:$E$5,MATCH($B11,Axes!$A$2:$A$5,0)) -> Improviser et inventer (créer sur le moment, faire autrement) | G11: =INDEX(Axes!$F$2:$F$5,MATCH($B11,Axes!$A$2:$A$5,0)) -> F | H11: =INDEX(Axes!$G$2:$G$5,MATCH($B11,Axes!$A$2:$A$5,0)) -> Préparer et fiabiliser (anticiper, vérifier) | I11: =INDEX(Axes!$H$2:$H$5,MATCH($B11,Axes!$A$2:$A$5,0)) -> Goût de la création ou de l'analyse et de la fiabilité | J11: =INDEX(Axes!$I$2:$I$5,MATCH($B11,Axes!$A$2:$A$5,0)) -> Créer et innover / Analyser et raisonner, Résoudre avec méthode | K11: Tu travailles mieux sous la pression de la dernière minute ? | L11: =SUBSTITUTE(Questions!G11,"Exemple : ","") -> un devoir est à rendre demain matin. Tu t'y mets la veille au soir, et c'est là que tes meilleures idées arrivent. | M11: =Questions!E11 -> I | N11: =IF(M11=E11,G11,E11) -> F | O11: =IF(Questions!F11="Oui","Oui","") | P11: 3 Design, développement, test et ops ; 2 Robotique et IoT ; 4 Data et IA ; 5 Marketing digital | Q11: Développeur·se d'applications ; UX / UI designer ; Expert·e en IA ; Community manager | R11: Arts plastiques ; Technologie ; Mathématiques ; Français | S11: Questions : version validée par Joelle (« C'est… que tu… »). Familles : « Le Numérique en 7 familles », France Travail. Rattachements pôle → famille indicatifs, à valider.
A12: =Questions!A12 -> 11 | B12: =Questions!B12 -> 3 | C12: =Questions!C12 -> Mon terrain | D12: =Questions!D12 -> C'est en disant clairement ce que tu penses, même si ça crée de la tension, que tu défends le mieux tes idées. | E12: =INDEX(Axes!$D$2:$D$5,MATCH($B12,Axes!$A$2:$A$5,0)) -> V | F12: =INDEX(Axes!$E$2:$E$5,MATCH($B12,Axes!$A$2:$A$5,0)) -> Côté visible (se montrer, être au contact) | G12: =INDEX(Axes!$F$2:$F$5,MATCH($B12,Axes!$A$2:$A$5,0)) -> C | H12: =INDEX(Axes!$G$2:$G$5,MATCH($B12,Axes!$A$2:$A$5,0)) -> Coulisses (rester en retrait, préparer) | I12: =INDEX(Axes!$H$2:$H$5,MATCH($B12,Axes!$A$2:$A$5,0)) -> Contact avec les utilisateurs ou travail en arrière-plan | J12: =INDEX(Axes!$I$2:$I$5,MATCH($B12,Axes!$A$2:$A$5,0)) -> Communiquer et expliquer / Apprendre à apprendre, Résoudre avec méthode | K12: Tu dis franchement ce que tu penses, même si ça crée de la tension ? | L12: =SUBSTITUTE(Questions!G12,"Exemple : ","") -> en débat, un camarade n'est pas d'accord avec toi. Tu expliques clairement pourquoi tu penses autrement, même si la discussion devient tendue. | M12: =Questions!E12 -> V | N12: =IF(M12=E12,G12,E12) -> C | O12: =IF(Questions!F12="Oui","Oui","") | P12: 5 Marketing digital, communication et e-commerce ; 7 Stratégie et gestion de projet ; 3 Design (UX) | Q12: Community manager ; Technico-commercial·e tech ; Chef·fe de projet digital ; UX / UI designer | R12: Français ; Anglais ; Arts plastiques ; Enseignement moral et civique | S12: Questions : version validée par Joelle (« C'est… que tu… »). Familles : « Le Numérique en 7 familles », France Travail. Rattachements pôle → famille indicatifs, à valider.
A13: =Questions!A13 -> 12 | B13: =Questions!B13 -> 4 | C13: =Questions!C13 -> Ma façon de travailler | D13: =Questions!D13 -> C'est quand tu te plonges à fond dans un sujet qui te passionne que tu deviens le plus fort(e). | E13: =INDEX(Axes!$D$2:$D$5,MATCH($B13,Axes!$A$2:$A$5,0)) -> E | F13: =INDEX(Axes!$E$2:$E$5,MATCH($B13,Axes!$A$2:$A$5,0)) -> Expertise en profondeur (je maîtrise à fond) | G13: =INDEX(Axes!$F$2:$F$5,MATCH($B13,Axes!$A$2:$A$5,0)) -> K | H13: =INDEX(Axes!$G$2:$G$5,MATCH($B13,Axes!$A$2:$A$5,0)) -> Collectif et coordination (je fais avancer ensemble) | I13: =INDEX(Axes!$H$2:$H$5,MATCH($B13,Axes!$A$2:$A$5,0)) -> Expertise individuelle ou travail collectif | J13: =INDEX(Axes!$I$2:$I$5,MATCH($B13,Axes!$A$2:$A$5,0)) -> Apprendre à apprendre, Se connaître et s'engager / Coopérer en équipe, S'adapter et rebondir | K13: Tu te passionnes à fond pour un sujet jusqu'à tout savoir dessus ? | L13: =SUBSTITUTE(Questions!G13,"Exemple : ","") -> tu découvres un sujet qui te passionne (dinosaures, code, musique) et tu y passes tes week-ends jusqu'à tout savoir dessus. | M13: =Questions!E13 -> E | N13: =IF(M13=E13,G13,E13) -> K | O13: =IF(Questions!F13="Oui","Oui","") | P13: 4 Data et IA ; 6 Cybersécurité ; 2 Robotique et IoT ; 3 Développement | Q13: Expert·e en IA ; Data scientist ; Pentesteur·se ; Spécialiste robotique | R13: Mathématiques ; Physique-chimie ; Technologie ; Anglais | S13: Questions : version validée par Joelle (« C'est… que tu… »). Familles : « Le Numérique en 7 familles », France Travail. Rattachements pôle → famille indicatifs, à valider.
... A33: =Questions!A33 -> 32 | B33: =Questions!B33 -> 4 | C33: =Questions!C33 -> Ma façon de travailler | D33: =Questions!D33 -> C'est en devenant le ou la spécialiste de quelque chose que tu te sens le plus accompli(e). | E33: =INDEX(Axes!$D$2:$D$5,MATCH($B33,Axes!$A$2:$A$5,0)) -> E | F33: =INDEX(Axes!$E$2:$E$5,MATCH($B33,Axes!$A$2:$A$5,0)) -> Expertise en profondeur (je maîtrise à fond) | G33: =INDEX(Axes!$F$2:$F$5,MATCH($B33,Axes!$A$2:$A$5,0)) -> K | H33: =INDEX(Axes!$G$2:$G$5,MATCH($B33,Axes!$A$2:$A$5,0)) -> Collectif et coordination (je fais avancer ensemble) | I33: =INDEX(Axes!$H$2:$H$5,MATCH($B33,Axes!$A$2:$A$5,0)) -> Expertise individuelle ou travail collectif | J33: =INDEX(Axes!$I$2:$I$5,MATCH($B33,Axes!$A$2:$A$5,0)) -> Apprendre à apprendre, Se connaître et s'engager / Coopérer en équipe, S'adapter et rebondir | K33: Tu veux devenir le ou la spécialiste d'un sujet ? | L33: =SUBSTITUTE(Questions!G33,"Exemple : ","") -> tu t'imagines dans dix ans : on vient te voir parce que tu es la personne qui connaît tout sur ton sujet. | M33: =Questions!E33 -> E | N33: =IF(M33=E33,G33,E33) -> K | O33: =IF(Questions!F33="Oui","Oui","") -> Oui | P33: 4 Data et IA ; 6 Cybersécurité ; 2 Robotique et IoT ; 3 Développement | Q33: Expert·e en IA ; Data scientist ; Pentesteur·se ; Spécialiste robotique | R33: Mathématiques ; Physique-chimie ; Technologie ; Anglais | S33: Questions : version validée par Joelle (« C'est… que tu… »). Familles : « Le Numérique en 7 familles », France Travail. Rattachements pôle → famille indicatifs, à valider.

Sheet Metiers
A1: Code V1 (4 lettres) | B1: Métier à présenter | C1: Profil RIASEC (V2) | D1: Description accessible collégiens | E1: Étape de l'anniversaire (image concrète) | F1: Compétences durables | G1: Matières à valoriser | H1: Voies de formation (pistes, à confirmer sur l'Onisep) | I1: Métier voisin à explorer | J1: Origine | K1: Statut | L1: Famille de rattachement principale | M1: Famille de rattachement secondaire | N1: Mission principale 1 | O1: Mission principale 2 | P1: Stage de 3ᵉ intéressant | Q1: 2 entreprises où postuler (à vérifier) | R1: Salaire annuel brut débutant (ordre de grandeur) | S1: Durée des études après le bac | T1: 2 qualités clés
A2: TIVE | B2: Développeur·se d'applications | C2: I-R | D2: Crée des jeux vidéo, des applications pour smartphones ou des logiciels en écrivant du code informatique. | E2: Réalisation : programme la page d'invitation | F2: Résoudre avec méthode ; Créer et innover ; Apprendre à apprendre | G2: Mathématiques ; Technologie ; Arts plastiques ; Anglais | H2: BTS SIO option SLAM ; BUT Informatique ; école d'ingénieurs ou d'informatique | I2: UX / UI designer | J2: Fichier de Joelle (Opiiec) | K2: À valider | L2: 3 – Design, développement, test et ops | M2: 2 – Robotique et objets connectés (IoT) | N2: Écrire le code des applications | O2: Corriger et améliorer le logiciel | P2: Équipe de développement ou studio de jeux vidéo | Q2: Ubisoft ; Dassault Systèmes | R2: 33 – 40 k€ | S2: 3 à 5 ans | T2: Logique et persévérance
A3: TIVK | B3: Spécialiste robotique et automatisation | C3: R-I | D3: Conçoit, fabrique et programme des robots capables d'aider les humains ou d'exécuter des tâches automatiques. | E3: Animation : construit un petit robot qui sert les boissons aux invités | F3: Résoudre avec méthode ; Créer et innover ; Coopérer en équipe | G3: Technologie ; Mathématiques ; Physique-chimie ; Arts plastiques | H3: Bac pro Systèmes numériques ; BUT Génie électrique et informatique industrielle ; école d'ingénieurs | I3: Développeur·se d'applications | J3: Fichier de Joelle (Opiiec) | K3: À valider | L3: 2 – Robotique et objets connectés (IoT) | M3: 3 – Design, développement, test et ops | N3: Concevoir et monter des robots | O3: Programmer leurs mouvements | P3: Atelier de robotique ou bureau d'études | Q3: Schneider Electric ; Naval Group | R3: 35 – 42 k€ | S3: 5 ans | T3: Esprit pratique et minutie
A4: TICE | B4: Expert·e en intelligence artificielle | C4: I-A | D4: Crée des programmes intelligents capables d'apprendre seuls, d'analyser des images ou de discuter comme des humains. | E4: Personnalisation : suggère une playlist selon les goûts des invités | F4: Analyser et raisonner ; Apprendre à apprendre ; Créer et innover | G4: Mathématiques ; Physique-chimie ; Technologie ; Anglais | H4: BUT Science des données ; licence puis master ; école d'ingénieurs | I4: Data scientist | J4: Fichier de Joelle (Opiiec) | K4: À valider | L4: 4 – Data et IA | M4: 3 – Design, développement, test et ops | N4: Entraîner des programmes intelligents | O4: Vérifier qu'ils ne se trompent pas | P4: Équipe data ou IA d'une entreprise | Q4: Dataiku ; Criteo | R4: 42 – 55 k€ | S4: 5 ans | T4: Curiosité et esprit d'analyse
A5: TICK | B5: Développeur·se back-end | C5: I-C | D5: Programme la partie cachée des applications : serveurs, bases de données et services. | E5: Coulisses : enregistre les réponses des invités | F5: Résoudre avec méthode ; Coopérer en équipe ; Analyser et raisonner | G5: Mathématiques ; Technologie ; Anglais ; Français | H5: BTS SIO option SLAM ; BUT Informatique ; école d'ingénieurs | I5: Spécialiste systèmes, réseaux et cloud | J5: Proposition ajoutée | K5: À valider | L5: 3 – Design, développement, test et ops | M5: 1 – Infrastructures, cloud et réseaux | N5: Programmer serveurs et bases de données | O5: Faire communiquer les applications | P5: Équipe de développement d'une application connue | Q5: Doctolib ; Sopra Steria | R5: 35 – 42 k€ | S5: 3 à 5 ans | T5: Logique et rigueur
A6: TFVE | B6: Data scientist | C6: I-C | D6: Fouille dans des montagnes de données et de chiffres pour y découvrir des informations cachées grâce aux maths. | E6: Bilan : montre ce qui a plu aux invités avec des graphiques | F6: Analyser et raisonner ; Communiquer et expliquer ; Résoudre avec méthode | G6: Mathématiques ; Histoire-géographie ; Français ; Technologie | H6: BUT Science des données ; licence puis master ; école d'ingénieurs | I6: Expert·e en intelligence artificielle | J6: Fichier de Joelle (Opiiec) | K6: À valider | L6: 4 – Data et IA | M6: 7 – Stratégie et gestion de projet | N6: Analyser les chiffres et les données | O6: Montrer les résultats en graphiques | P6: Équipe data ou études statistiques | Q6: Criteo ; Orange | R6: 40 – 50 k€ | S6: 5 ans | T6: Esprit d'analyse et clarté
A7: TFVK | B7: Testeur·se et ingénieur·e qualité | C7: C-I | D7: Teste les logiciels en équipe pour trouver les défauts avant les utilisateurs. | E7: Répétition générale : teste l'appli d'invitation sur plusieurs téléphones | F7: Analyser et raisonner ; Coopérer en équipe ; Communiquer et expliquer | G7: Mathématiques ; Technologie ; Français ; Anglais | H7: BTS SIO ; BUT Informatique ; formations spécialisées en test logiciel | I7: Développeur·se d'applications | J7: Proposition ajoutée | K7: À valider | L7: 3 – Design, développement, test et ops | M7: 6 – Cybersécurité et sûreté des systèmes d'information | N7: Tester les logiciels avant leur sortie | O7: Signaler et suivre les bugs | P7: Équipe qualité d'un éditeur de logiciels ou de jeux | Q7: Capgemini ; Ubisoft | R7: 32 – 38 k€ | S7: 2 à 5 ans | T7: Minutie et patience
A8: TFCE | B8: Pentesteur·se / analyste cybersécurité | C8: I-R | D8: Joue au cyber-détective : essaie de s'introduire dans les systèmes pour trouver leurs failles de sécurité et les protéger. | E8: Protection : sécurise la liste d'invités et les photos partagées | F8: Analyser et raisonner ; Résoudre avec méthode ; Apprendre à apprendre | G8: Mathématiques ; Technologie ; Anglais ; Enseignement moral et civique | H8: BTS CIEL ; BUT Réseaux et télécommunications parcours cybersécurité ; école d'ingénieurs | I8: Délégué·e à la protection des données (DPO) | J8: Fichier de Joelle (Opiiec) | K8: À valider | L8: 6 – Cybersécurité et sûreté des systèmes d'information | M8: 1 – Infrastructures, cloud et réseaux | N8: Chercher les failles d'un système | O8: Expliquer comment les corriger | P8: Équipe sécurité informatique | Q8: Orange Cyberdefense ; Thales | R8: 38 – 48 k€ | S8: 3 à 5 ans | T8: Ruse et éthique
A9: TFCK | B9: Spécialiste systèmes, réseaux et cloud | C9: R-C | D9: Installe et entretient serveurs, réseaux et connexions internet pour que tout le monde reste connecté. | E9: Jour J : garde le Wi-Fi et l'appli en ligne même si tous les invités se connectent | F9: Résoudre avec méthode ; Coopérer en équipe ; S'adapter et rebondir | G9: Mathématiques ; Technologie ; Physique-chimie ; Anglais | H9: Bac pro Systèmes numériques ; BTS SIO option SISR ; BUT Réseaux et télécommunications ; école d'ingénieurs | I9: Pentesteur·se / analyste cybersécurité | J9: Fichier de Joelle (Opiiec) | K9: À valider | L9: 1 – Infrastructures, cloud et réseaux | M9: 6 – Cybersécurité et sûreté des systèmes d'information | N9: Installer réseaux, serveurs et cloud | O9: Surveiller que tout fonctionne | P9: Salle serveurs ou service informatique | Q9: OVHcloud ; Orange | R9: 33 – 40 k€ | S9: 2 à 5 ans | T9: Rigueur et sang-froid
A10: HIVE | B10: UX / UI designer | C10: A-I | D10: Imagine le visuel, les couleurs et la facilité d'utilisation des sites web et des applications mobiles. | E10: Conception : dessine l'écran d'invitation | F10: Créer et innover ; Communiquer et expliquer ; Apprendre à apprendre | G10: Arts plastiques ; Français ; Technologie ; Histoire-géographie | H10: BUT Métiers du multimédia et de l'internet ; DN MADE numérique ; écoles de design | I10: Community manager | J10: Fichier de Joelle (Opiiec) | K10: À valider | L10: 3 – Design, développement, test et ops | M10: 5 – Marketing digital, communication et e-commerce | N10: Dessiner des écrans simples à utiliser | O10: Tester avec de vrais utilisateurs | P10: Studio de design ou agence web | Q10: Doctolib ; Publicis | R10: 32 – 40 k€ | S10: 3 à 5 ans | T10: Créativité et sens de l'écoute
A11: HIVK | B11: Community manager | C11: S-A | D11: Anime et gère la communauté d'une marque ou d'un jeu vidéo sur les réseaux sociaux. | E11: Communication : anime le groupe des invités et répond à leurs questions avant la fête | F11: Communiquer et expliquer ; Créer et innover ; S'adapter et rebondir | G11: Français ; Anglais ; Arts plastiques ; Histoire-géographie | H11: BUT Information-communication ou Métiers du multimédia ; licence information-communication | I11: Chef·fe de projet digital | J11: Fichier de Joelle (Opiiec) | K11: À valider | L11: 5 – Marketing digital, communication et e-commerce | M11: 7 – Stratégie et gestion de projet | N11: Animer les réseaux sociaux | O11: Répondre à la communauté | P11: Agence de communication ou service communication | Q11: Havas ; Publicis | R11: 27 – 33 k€ | S11: 3 à 5 ans | T11: Dynamisme et sens du contact
A12: HICE | B12: Responsable Green IT / éco-conception | C12: S-I | D12: Supervise la technologie pour qu'elle consomme moins d'énergie et soit plus écologique. | E12: Bilan : réduit l'énergie et le gaspillage de la fête numérique (écrans, serveurs) | F12: Analyser et raisonner ; Se connaître et s'engager ; Communiquer et expliquer | G12: SVT ; Technologie ; Physique-chimie ; Mathématiques | H12: BUT Informatique ou Génie industriel ; école d'ingénieurs avec option numérique responsable | I12: Spécialiste systèmes, réseaux et cloud | J12: Fichier de Joelle (Opiiec) | K12: À valider | L12: 1 – Infrastructures, cloud et réseaux | M12: 7 – Stratégie et gestion de projet | N12: Réduire l'énergie du numérique | O12: Concevoir des services plus sobres | P12: Équipe numérique responsable d'un grand groupe | Q12: Capgemini ; Orange | R12: 36 – 45 k€ | S12: 5 ans | T12: Conscience écologique et esprit de synthèse
... A17: HFCK | B17: Chef·fe de projet digital | C17: E-S | D17: Chef d'orchestre du numérique : coordonne les équipes (développeurs, designers) pour créer un site ou une appli à temps. | E17: Pilotage : coordonne lieu, budget et prestataires pour tenir la date | F17: Coopérer en équipe ; Communiquer et expliquer ; Résoudre avec méthode | G17: Mathématiques ; Français ; Anglais ; Histoire-géographie | H17: BUT ou licence puis master ; école d'ingénieurs ou de commerce | I17: Technico-commercial·e tech | J17: Fichier de Joelle (Opiiec) | K17: À valider | L17: 7 – Stratégie et gestion de projet | M17: 3 – Design, développement, test et ops | N17: Diriger et organiser les projets | O17: Tenir les délais et le budget | P17: Chef de projet dans une entreprise de services numériques | Q17: Capgemini ; Sopra Steria | R17: 38 – 48 k€ | S17: 5 ans | T17: Leadership et sens de l'organisation
A19: Salaires : ordres de grandeur bruts annuels pour un début de carrière en France, hors primes, à confirmer (APEC, Opiiec, Onisep). Durées : après le bac, selon la voie choisie (BTS/BUT 2-3 ans, master ou école d'ingénieurs 5 ans). Entreprises : exemples, à vérifier.

Sheet Familles
A1: N° | B1: Famille de métiers (France Travail) | C1: Domaines couverts | D1: Métiers du jeu rattachés (famille principale) | E1: Métiers du jeu voisins (famille voisine) | F1: Pôles les plus associés | G1: Cursus d'étude le plus adapté (à confirmer sur l'Onisep) | H1: Mission principale 1 | I1: Mission principale 2 | J1: Matières indispensables au lycée | K1: Matières souhaitables | L1: Stage de 3ᵉ intéressant | M1: 2 entreprises où postuler (à vérifier) | N1: 2 qualités clés
